Workbook

Sheet DATA>>>

Sheet DATA_2025
A1: Année | B1: Semester | C1: Quarter | D1: Mois | E1: Mois_Num | F1: Date | G1: Jour_Semaine | H1: Segment_Fidelite | I1: Prix_Base_€ | J1: Discount_Segment_% | K1: Discount_Promo_% | L1: Discount_Total_% | M1: Prix_Final_€ | N1: Units_Vendues | O1: Discount_Weighted_Units | P1: Discounte_Promo_Weighted | Q1: CA_€ | R1: Cout_Produit_€ | S1: Cout_Total_€ | T1: Marge_Brute_€ | U1: Marketing_Spend_€ | V1: Marge_Contributive_€ | W1: Type_Promotion | X1: Periode_Speciale
A2: 2025 | B2: S1 | C2: Q1 | D2: January | E2: 1 | F2: 2025-01-01 | G2: Wednesday | H2: Single | I2: 34 | J2: 0 | K2: 0 | L2: 0 | M2: 34 | N2: 93 | O2: 0 | P2: 0 | Q2: 3162 | R2: 9 | S2: 837 | T2: 2325 | U2: 474.3 | V2: 1850.7 | W2: Baseline | X2: Non
A3: 2025 | B3: S1 | C3: Q1 | D3: January | E3: 1 | F3: 2025-01-01 | G3: Wednesday | H3: Aura Glow | I3: 34 | J3: 10 | K3: 0 | L3: 10 | M3: 30.6 | N3: 46 | O3: 460 | P3: 0 | Q3: 1407.6 | R3: 9 | S3: 414 | T3: 993.6 | U3: 211.14 | V3: 782.46 | W3: Baseline | X3: Non
A4: 2025 | B4: S1 | C4: Q1 | D4: January | E4: 1 | F4: 2025-01-01 | G4: Wednesday | H4: Aura Radiance | I4: 34 | J4: 15 | K4: 0 | L4: 15 | M4: 28.9 | N4: 27 | O4: 405 | P4: 0 | Q4: 780.3 | R4: 9 | S4: 243 | T4: 537.3 | U4: 117.04 | V4: 420.25 | W4: Baseline | X4: Non
A5: 2025 | B5: S1 | C5: Q1 | D5: January | E5: 1 | F5: 2025-01-01 | G5: Wednesday | H5: Aura Icon | I5: 34 | J5: 20 | K5: 0 | L5: 20 | M5: 27.2 | N5: 18 | O5: 360 | P5: 0 | Q5: 489.6 | R5: 9 | S5: 162 | T5: 327.6 | U5: 73.44 | V5: 254.16 | W5: Baseline | X5: Non
A6: 2025 | B6: S1 | C6: Q1 | D6: January | E6: 1 | F6: 2025-01-02 | G6: Thursday | H6: Single | I6: 34 | J6: 0 | K6: 0 | L6: 0 | M6: 34 | N6: 79 | O6: 0 | P6: 0 | Q6: 2686 | R6: 9 | S6: 711 | T6: 1975 | U6: 402.9 | V6: 1572.1 | W6: Baseline | X6: Non
A7: 2025 | B7: S1 | C7: Q1 | D7: January | E7: 1 | F7: 2025-01-02 | G7: Thursday | H7: Aura Glow | I7: 34 | J7: 10 | K7: 0 | L7: 10 | M7: 30.6 | N7: 39 | O7: 390 | P7: 0 | Q7: 1193.4 | R7: 9 | S7: 351 | T7: 842.4 | U7: 179.01 | V7: 663.39 | W7: Baseline | X7: Non
A8: 2025 | B8: S1 | C8: Q1 | D8: January | E8: 1 | F8: 2025-01-02 | G8: Thursday | H8: Aura Radiance | I8: 34 | J8: 15 | K8: 0 | L8: 15 | M8: 28.9 | N8: 23 | O8: 345 | P8: 0 | Q8: 664.7 | R8: 9 | S8: 207 | T8: 457.7 | U8: 99.7 | V8: 357.99 | W8: Baseline | X8: Non
A9: 2025 | B9: S1 | C9: Q1 | D9: January | E9: 1 | F9: 2025-01-02 | G9: Thursday | H9: Aura Icon | I9: 34 | J9: 20 | K9: 0 | L9: 20 | M9: 27.2 | N9: 15 | O9: 300 | P9: 0 | Q9: 408 | R9: 9 | S9: 135 | T9: 273 | U9: 61.2 | V9: 211.8 | W9: Baseline | X9: Non
A10: 2025 | B10: S1 | C10: Q1 | D10: January | E10: 1 | F10: 2025-01-03 | G10: Friday | H10: Single | I10: 34 | J10: 0 | K10: 0 | L10: 0 | M10: 34 | N10: 110 | O10: 0 | P10: 0 | Q10: 3740 | R10: 9 | S10: 990 | T10: 2750 | U10: 561 | V10: 2189 | W10: Baseline | X10: Non
A11: 2025 | B11: S1 | C11: Q1 | D11: January | E11: 1 | F11: 2025-01-03 | G11: Friday | H11: Aura Glow | I11: 34 | J11: 10 | K11: 0 | L11: 10 | M11: 30.6 | N11: 55 | O11: 550 | P11: 0 | Q11: 1683 | R11: 9 | S11: 495 | T11: 1188 | U11: 252.45 | V11: 935.55 | W11: Baseline | X11: Non
A12: 2025 | B12: S1 | C12: Q1 | D12: January | E12: 1 | F12: 2025-01-03 | G12: Friday | H12: Aura Radiance | I12: 34 | J12: 15 | K12: 0 | L12: 15 | M12: 28.9 | N12: 33 | O12: 495 | P12: 0 | Q12: 953.7 | R12: 9 | S12: 297 | T12: 656.7 | U12: 143.05 | V12: 513.64 | W12: Baseline | X12: Non
A13: 2025 | B13: S1 | C13: Q1 | D13: January | E13: 1 | F13: 2025-01-03 | G13: Friday | H13: Aura Icon | I13: 34 | J13: 20 | K13: 0 | L13: 20 | M13: 27.2 | N13: 22 | O13: 440 | P13: 0 | Q13: 598.4 | R13: 9 | S13: 198 | T13: 400.4 | U13: 89.76 | V13: 310.64 | W13: Baseline | X13: Non
... A1461: 2025 | B1461: S2 | C1461: Q4 | D1461: December | E1461: 12 | F1461: 2025-12-31 | G1461: Wednesday | H1461: Aura Icon | I1461: 34 | J1461: 20 | K1461: 0 | L1461: 20 | M1461: 27.2 | N1461: 19 | O1461: 380 | P1461: 0 | Q1461: 516.8 | R1461: 9 | S1461: 171 | T1461: 345.8 | U1461: 77.52 | V1461: 268.28 | W1461: Baseline | X1461: Non

Sheet BENCHMARK_FENTY_2024
A1: Année | B1: Semester | C1: Quarter | D1: Mois | E1: Mois_Num | F1: Date | G1: Jour_Semaine | H1: Produit | I1: Prix_€ | J1: Units_Vendues | K1: CA_€
A2: 2024 | B2: =IF(OR(C2="Q1",C2="Q2"),"S1",IF(OR(C2="Q3",C2="Q4"),"S2","")) -> S1 | C2: Q1 | D2: January | E2: 1 | F2: 2024-01-01 | G2: Monday | H2: Fenty Pro Filt'r SPF | I2: 38 | J2: 278 | K2: 10564
A3: 2024 | B3: =IF(OR(C3="Q1",C3="Q2"),"S1",IF(OR(C3="Q3",C3="Q4"),"S2","")) -> S1 | C3: Q1 | D3: January | E3: 1 | F3: 2024-01-02 | G3: Tuesday | H3: Fenty Pro Filt'r SPF | I3: 38 | J3: 288 | K3: 10944
A4: 2024 | B4: =IF(OR(C4="Q1",C4="Q2"),"S1",IF(OR(C4="Q3",C4="Q4"),"S2","")) -> S1 | C4: Q1 | D4: January | E4: 1 | F4: 2024-01-03 | G4: Wednesday | H4: Fenty Pro Filt'r SPF | I4: 38 | J4: 357 | K4: 13566
A5: 2024 | B5: =IF(OR(C5="Q1",C5="Q2"),"S1",IF(OR(C5="Q3",C5="Q4"),"S2","")) -> S1 | C5: Q1 | D5: January | E5: 1 | F5: 2024-01-04 | G5: Thursday | H5: Fenty Pro Filt'r SPF | I5: 38 | J5: 308 | K5: 11704
A6: 2024 | B6: =IF(OR(C6="Q1",C6="Q2"),"S1",IF(OR(C6="Q3",C6="Q4"),"S2","")) -> S1 | C6: Q1 | D6: January | E6: 1 | F6: 2024-01-05 | G6: Friday | H6: Fenty Pro Filt'r SPF | I6: 38 | J6: 419 | K6: 15922
A7: 2024 | B7: =IF(OR(C7="Q1",C7="Q2"),"S1",IF(OR(C7="Q3",C7="Q4"),"S2","")) -> S1 | C7: Q1 | D7: January | E7: 1 | F7: 2024-01-06 | G7: Saturday | H7: Fenty Pro Filt'r SPF | I7: 38 | J7: 457 | K7: 17366
A8: 2024 | B8: =IF(OR(C8="Q1",C8="Q2"),"S1",IF(OR(C8="Q3",C8="Q4"),"S2","")) -> S1 | C8: Q1 | D8: January | E8: 1 | F8: 2024-01-07 | G8: Sunday | H8: Fenty Pro Filt'r SPF | I8: 38 | J8: 296 | K8: 11248
A9: 2024 | B9: =IF(OR(C9="Q1",C9="Q2"),"S1",IF(OR(C9="Q3",C9="Q4"),"S2","")) -> S1 | C9: Q1 | D9: January | E9: 1 | F9: 2024-01-08 | G9: Monday | H9: Fenty Pro Filt'r SPF | I9: 38 | J9: 257 | K9: 9766
A10: 2024 | B10: =IF(OR(C10="Q1",C10="Q2"),"S1",IF(OR(C10="Q3",C10="Q4"),"S2","")) -> S1 | C10: Q1 | D10: January | E10: 1 | F10: 2024-01-09 | G10: Tuesday | H10: Fenty Pro Filt'r SPF | I10: 38 | J10: 271 | K10: 10298
A11: 2024 | B11: =IF(OR(C11="Q1",C11="Q2"),"S1",IF(OR(C11="Q3",C11="Q4"),"S2","")) -> S1 | C11: Q1 | D11: January | E11: 1 | F11: 2024-01-10 | G11: Wednesday | H11: Fenty Pro Filt'r SPF | I11: 38 | J11: 318 | K11: 12084
A12: 2024 | B12: =IF(OR(C12="Q1",C12="Q2"),"S1",IF(OR(C12="Q3",C12="Q4"),"S2","")) -> S1 | C12: Q1 | D12: January | E12: 1 | F12: 2024-01-11 | G12: Thursday | H12: Fenty Pro Filt'r SPF | I12: 38 | J12: 341 | K12: 12958
A13: 2024 | B13: =IF(OR(C13="Q1",C13="Q2"),"S1",IF(OR(C13="Q3",C13="Q4"),"S2","")) -> S1 | C13: Q1 | D13: January | E13: 1 | F13: 2024-01-12 | G13: Friday | H13: Fenty Pro Filt'r SPF | I13: 38 | J13: 442 | K13: 16796
... A367: 2024 | B367: =IF(OR(C367="Q1",C367="Q2"),"S1",IF(OR(C367="Q3",C367="Q4"),"S2","")) -> S2 | C367: Q4 | D367: December | E367: 12 | F367: 2024-12-31 | G367: Tuesday | H367: Fenty Pro Filt'r SPF | I367: 38 | J367: 426 | K367: 16188
B368: =IF(OR(C368="Q1",C368="Q2"),"S1",IF(OR(C368="Q3",C368="Q4"),"S2",""))
B369: =IF(OR(C369="Q1",C369="Q2"),"S1",IF(OR(C369="Q3",C369="Q4"),"S2",""))
B370: =IF(OR(C370="Q1",C370="Q2"),"S1",IF(OR(C370="Q3",C370="Q4"),"S2",""))
B371: =IF(OR(C371="Q1",C371="Q2"),"S1",IF(OR(C371="Q3",C371="Q4"),"S2",""))
B372: =IF(OR(C372="Q1",C372="Q2"),"S1",IF(OR(C372="Q3",C372="Q4"),"S2",""))
B373: =IF(OR(C373="Q1",C373="Q2"),"S1",IF(OR(C373="Q3",C373="Q4"),"S2",""))
B374: =IF(OR(C374="Q1",C374="Q2"),"S1",IF(OR(C374="Q3",C374="Q4"),"S2",""))
B375: =IF(OR(C375="Q1",C375="Q2"),"S1",IF(OR(C375="Q3",C375="Q4"),"S2",""))
B376: =IF(OR(C376="Q1",C376="Q2"),"S1",IF(OR(C376="Q3",C376="Q4"),"S2",""))
B377: =IF(OR(C377="Q1",C377="Q2"),"S1",IF(OR(C377="Q3",C377="Q4"),"S2",""))
B378: =IF(OR(C378="Q1",C378="Q2"),"S1",IF(OR(C378="Q3",C378="Q4"),"S2",""))
B379: =IF(OR(C379="Q1",C379="Q2"),"S1",IF(OR(C379="Q3",C379="Q4"),"S2",""))
... B1461: =IF(OR(C1461="Q1",C1461="Q2"),"S1",IF(OR(C1461="Q3",C1461="Q4"),"S2",""))

Sheet FORECAST_2025
A1: Année | B1: Semester | C1: Quarter | D1: Mois | E1: Mois_Num | F1: Date | G1: Jour_Semaine | H1: Segment_Fidelite | I1: Units_Forecast | J1: CA_Forecast_€ | K1: Prix_Moyen_Forecast_€
A2: 2025 | B2: =IF(OR(C2="Q1",C2="Q2"),"S1",IF(OR(C2="Q3",C2="Q4"),"S2","")) -> S1 | C2: Q1 | D2: January | E2: 1 | F2: 2025-01-01 | G2: Wednesday | H2: Single | I2: 72 | J2: 2448 | K2: 34
A3: 2025 | B3: =IF(OR(C3="Q1",C3="Q2"),"S1",IF(OR(C3="Q3",C3="Q4"),"S2","")) -> S1 | C3: Q1 | D3: January | E3: 1 | F3: 2025-01-01 | G3: Wednesday | H3: Aura Glow | I3: 54 | J3: 1652.4 | K3: 30.6
A4: 2025 | B4: =IF(OR(C4="Q1",C4="Q2"),"S1",IF(OR(C4="Q3",C4="Q4"),"S2","")) -> S1 | C4: Q1 | D4: January | E4: 1 | F4: 2025-01-01 | G4: Wednesday | H4: Aura Radiance | I4: 36 | J4: 1040.4 | K4: 28.9
A5: 2025 | B5: =IF(OR(C5="Q1",C5="Q2"),"S1",IF(OR(C5="Q3",C5="Q4"),"S2","")) -> S1 | C5: Q1 | D5: January | E5: 1 | F5: 2025-01-01 | G5: Wednesday | H5: Aura Icon | I5: 18 | J5: 489.6 | K5: 27.2
A6: 2025 | B6: =IF(OR(C6="Q1",C6="Q2"),"S1",IF(OR(C6="Q3",C6="Q4"),"S2","")) -> S1 | C6: Q1 | D6: January | E6: 1 | F6: 2025-01-02 | G6: Thursday | H6: Single | I6: 69 | J6: 2346 | K6: 34
A7: 2025 | B7: =IF(OR(C7="Q1",C7="Q2"),"S1",IF(OR(C7="Q3",C7="Q4"),"S2","")) -> S1 | C7: Q1 | D7: January | E7: 1 | F7: 2025-01-02 | G7: Thursday | H7: Aura Glow | I7: 51 | J7: 1560.6 | K7: 30.6
A8: 2025 | B8: =IF(OR(C8="Q1",C8="Q2"),"S1",IF(OR(C8="Q3",C8="Q4"),"S2","")) -> S1 | C8: Q1 | D8: January | E8: 1 | F8: 2025-01-02 | G8: Thursday | H8: Aura Radiance | I8: 34 | J8: 982.6 | K8: 28.9
A9: 2025 | B9: =IF(OR(C9="Q1",C9="Q2"),"S1",IF(OR(C9="Q3",C9="Q4"),"S2","")) -> S1 | C9: Q1 | D9: January | E9: 1 | F9: 2025-01-02 | G9: Thursday | H9: Aura Icon | I9: 17 | J9: 462.4 | K9: 27.2
A10: 2025 | B10: =IF(OR(C10="Q1",C10="Q2"),"S1",IF(OR(C10="Q3",C10="Q4"),"S2","")) -> S1 | C10: Q1 | D10: January | E10: 1 | F10: 2025-01-03 | G10: Friday | H10: Single | I10: 85 | J10: 2890 | K10: 34
A11: 2025 | B11: =IF(OR(C11="Q1",C11="Q2"),"S1",IF(OR(C11="Q3",C11="Q4"),"S2","")) -> S1 | C11: Q1 | D11: January | E11: 1 | F11: 2025-01-03 | G11: Friday | H11: Aura Glow | I11: 64 | J11: 1958.4 | K11: 30.6
A12: 2025 | B12: =IF(OR(C12="Q1",C12="Q2"),"S1",IF(OR(C12="Q3",C12="Q4"),"S2","")) -> S1 | C12: Q1 | D12: January | E12: 1 | F12: 2025-01-03 | G12: Friday | H12: Aura Radiance | I12: 42 | J12: 1213.8 | K12: 28.9
A13: 2025 | B13: =IF(OR(C13="Q1",C13="Q2"),"S1",IF(OR(C13="Q3",C13="Q4"),"S2","")) -> S1 | C13: Q1 | D13: January | E13: 1 | F13: 2025-01-03 | G13: Friday | H13: Aura Icon | I13: 21 | J13: 571.2 | K13: 27.2
... A1461: 2025 | B1461: =IF(OR(C1461="Q1",C1461="Q2"),"S1",IF(OR(C1461="Q3",C1461="Q4"),"S2","")) -> S2 | C1461: Q4 | D1461: December | E1461: 12 | F1461: 2025-12-31 | G1461: Wednesday | H1461: Aura Icon | I1461: 24 | J1461: 652.8 | K1461: 27.2

Sheet CALENDRIER_PROMO
A1: CALENDRIER PROMOTIONNEL AURA SHADE
A2: Historique 2025 + Planning 2026
A4: Annee | B4: Periode | C4: Date_Debut | D4: Date_Fin | E4: Duree_Jours | F4: Type_Promo | G4: Discount_% | H4: Mecanique | I4: Intensite_Comm | J4: Budget_Marketing_€ | K4: Objectif_Units | L4: Statut | M4: Resultat_Units | N4: Performance | O4: CA_Genere_€ | P4: ROI | Q4: Commentaires
A5: 2025 | B5: Lancement Premium | C5: 2025-01-06 | D5: 2025-01-31 | E5: 26 | F5: Launch Campaign | G5: 0 | H5: Campagne media 360 - No discount | I5: Tres Haute | J5: 450000 | K5: 9000 | L5: Realise | M5: 11904 | N5: Surperformance +32% | O5: 372419 | P5: 15% | Q5: Lancement exceptionnel, forte adoption segment Icon
A6: 2025 | B6: Saint-Valentin | C6: 2025-02-10 | D6: 2025-02-16 | E6: 7 | F6: Seasonal | G6: 0 | H6: Coffret duo Glow Together 60€ | I6: Moyenne | J6: 35000 | K6: 1500 | L6: Realise | M6: 1708 | N6: Surperformance +14% | O6: 53439.5 | P6: 232% | Q6: Coffret tres performant, a reconduire
A7: 2025 | B7: Spring Beauty Sale | C7: 2025-03-17 | D7: 2025-03-23 | E7: 7 | F7: Promotional | G7: 15 | H7: -15% sur toute la gamme | I7: Haute | J7: 55000 | K7: 3000 | L7: Realise | M7: 4414 | N7: Surperformance +47% | O7: 126816.6 | P7: 66% | Q7: Performance tres forte grace au boost promo
A8: 2025 | B8: Fete des Meres | C8: 2025-05-19 | D8: 2025-05-31 | E8: 13 | F8: Seasonal | G8: 0 | H8: Coffret Premium + carte personnalisee | I8: Haute | J8: 75000 | K8: 4000 | L8: Realise | M8: 4814 | N8: Surperformance +20% | O8: 150604.7 | P8: 137% | Q8: Meilleure periode saisonniere hors BF
A9: 2025 | B9: Soldes Ete | C9: 2025-06-23 | D9: 2025-07-06 | E9: 14 | F9: Clearance | G9: 20 | H9: -20% soldes legales | I9: Faible | J9: 15000 | K9: 3500 | L9: Realise | M9: 4713 | N9: Surperformance +35% | O9: 128193.6 | P9: 240% | Q9: Soldes performantes malgre periode creuse
A10: 2025 | B10: Back to Work Glow | C10: 2025-08-25 | D10: 2025-09-07 | E10: 14 | F10: Seasonal | G10: 0 | H10: Routine rentree - Bundle serum + primer | I10: Moyenne | J10: 45000 | K10: 2800 | L10: Realise | M10: 3112 | N10: Surperformance +11% | O10: 97370.9 | P10: 153% | Q10: Bundle rentree a reconduire
A11: 2025 | B11: Single Day | C11: 2025-11-11 | D11: 2025-11-11 | E11: 1 | F11: Flash Sale | G11: 20 | H11: -20% journee unique | I11: Tres Haute | J11: 85000 | K11: 800 | L11: Realise | M11: 1000 | N11: Surperformance +25% | O11: 27200 | P11: 99% | Q11: Evenement concentre, forte acquisition
A12: 2025 | B12: Black Friday | C12: 2025-11-28 | D12: 2025-11-30 | E12: 3 | F12: Mega Sale | G12: 30 | H12: -30% Black Friday | I12: Tres Haute | J12: 125000 | K12: 4500 | L12: Realise | M12: 5406 | N12: Surperformance +20% | O12: 128662.8 | P12: 99% | Q12: Peak absolu de annee, forte pression marge
A13: 2025 | B13: Cyber Monday | C13: 2025-12-01 | D13: 2025-12-01 | E13: 1 | F13: Flash Sale | G13: 25 | H13: -25% + livraison offerte | I13: Tres Haute | J13: 65000 | K13: 700 | L13: Realise | M13: 864 | N13: Surperformance +23% | O13: 22032 | P13: 123% | Q13: Prolongation BF reussie
A14: 2025 | B14: Coffrets de Noel | C14: 2025-12-08 | D14: 2025-12-24 | E14: 17 | F14: Seasonal | G14: 0 | H14: Coffrets cadeaux premium 75-120€ | I14: Haute | J14: 95000 | K14: 5000 | L14: Realise | M14: 5904 | N14: Surperformance +18% | O14: 184708.4 | P14: 143% | Q14: Gifting tres fort, marges preservees
A15: 2026 | B15: Galette des Reines | C15: 2026-01-05 | D15: 2026-01-11 | E15: 7 | F15: Seasonal | G15: 0 | H15: Mini-size offert des 2 produits | I15: Moyenne | J15: 25000 | K15: 2500 | L15: Planifie | Q15: Test acquisition debut annee
A16: 2026 | B16: Saint-Valentin 2026 | C16: 2026-02-09 | D16: 2026-02-15 | E16: 7 | F16: Seasonal | G16: 0 | H16: Coffret duo Radiant Love 65€ | I16: Haute | J16: 45000 | K16: 3800 | L16: Planifie | Q16: Reconduction coffret 2025 avec upgrade
A17: 2026 | B17: Journee de la Femme | C17: 2026-03-08 | D17: 2026-03-08 | E17: 1 | F17: Cause Marketing | G17: 0 | H17: 5€ reverses a asso + contenu empowerment | I17: Tres Haute | J17: 75000 | K17: 4000 | L17: Planifie | Q17: Activation brand purpose forte
A18: 2026 | B18: Spring Refresh | C18: 2026-03-23 | D18: 2026-03-29 | E18: 7 | F18: Promotional | G18: 10 | H18: -10% nouveaux clients uniquement | I18: Moyenne | J18: 35000 | K18: 2800 | L18: Planifie | Q18: Acquisition ciblee printemps
A19: 2026 | B19: Fete des Meres 2026 | C19: 2026-05-18 | D19: 2026-05-31 | E19: 14 | F19: Seasonal | G19: 0 | H19: Coffret Prestige + gravure personnalisee | I19: Tres Haute | J19: 95000 | K19: 6500 | L19: Planifie | Q19: Montee en gamme vs 2025
A20: 2026 | B20: Soldes Ete 2026 | C20: 2026-06-24 | D20: 2026-07-07 | E20: 14 | F20: Clearance | G20: 20 | H20: -20% soldes legales | I20: Faible | J20: 18000 | K20: 2200 | L20: Planifie | Q20: Obligation legale, marge preservee
A21: 2026 | B21: Back to Glow 2026 | C21: 2026-08-24 | D21: 2026-09-06 | E21: 14 | F21: Seasonal | G21: 0 | H21: Routine complete serum+hydratant+SPF | I21: Haute | J21: 55000 | K21: 4200 | L21: Planifie | Q21: Extension gamme anticipee pour rentree
A22: 2026 | B22: 2eme Anniversaire | C22: 2026-09-14 | D22: 2026-09-20 | E22: 7 | F22: Anniversary | G22: 15 | H22: -15% membres Aura Society + cadeaux | I22: Tres Haute | J22: 85000 | K22: 5500 | L22: Planifie | Q22: Celebration 2 ans, fidelisation massive

Sheet BUSINESS PERFORMANCE >>>

Sheet 1.DASHBOARD PERFORMANCE
K1: CY | M1: 2025 | N1: 2025 | O1: 2025 | P1: 2025 | Q1: 2025 | R1: 2025 | S1: 2025 | T1: 2025 | U1: 2025 | V1: 2025 | W1: 2025 | X1: 2025 | Z1: 2025 | AA1: 2025 | AB1: 2025 | AC1: 2025 | AE1: 2025 | AF1: 2025 | AH1: 2025
K2: PY | M2: 2024 | N2: 2024 | O2: 2024 | P2: 2024 | Q2: 2024 | R2: 2024 | S2: 2024 | T2: 2024 | U2: 2024 | V2: 2024 | W2: 2024 | X2: 2024 | Z2: 2024 | AA2: 2024 | AB2: 2024 | AC2: 2024 | AE2: 2024 | AF2: 2024 | AH2: 2024
K3: #day | M3: 31 | N3: 30 | O3: 31 | P3: 31 | Q3: 28 | R3: 31 | S3: 30 | T3: 31 | U3: 30 | V3: 31 | W3: 31 | X3: 30 | Z3: =SUM(M3:O3) -> 92 | AA3: =SUM(P3:R3) -> 90 | AB3: =SUM(S3:U3) -> 91 | AC3: =SUM(V3:X3) -> 92 | AE3: =Z3+AA3 -> 182 | AF3: =AB3+AC3 -> 183 | AH3: =AF3+AE3 -> 365
K4: month number | M4: 1 | N4: 2 | O4: 3 | P4: 4 | Q4: 5 | R4: 6 | S4: 7 | T4: 8 | U4: 9 | V4: 10 | W4: 11 | X4: 12 | Z4: 1 | AA4: 2 | AB4: 3 | AC4: 4
M5: 1 | N5: 2 | O5: 3 | P5: 4 | Q5: 5 | R5: 6 | S5: 7 | T5: 8 | U5: 9 | V5: 10 | W5: 11 | X5: 12 | Z5: Q1 | AA5: Q2 | AB5: Q3 | AC5: Q4 | AE5: S1 | AF5: S2 | AH5: CY25
M7: Jan | N7: Feb | O7: Mar | P7: Apr | Q7: May | R7: Jun | S7: Jul | T7: Aug | U7: Sep | V7: Oct | W7: Nov | X7: Dec | Z7: Q1 | AA7: Q2 | AB7: Q3 | AC7: Q4 | AE7: S1 | AF7: S2 | AH7: Full Year
D9: ALL CLIENTS GROUP | F9: SALES PERFORMANCE
H10: Daily Sales Units | M10: =M15/M$3 -> 414.74194 | N10: =N15/N$3 -> 187.53333 | O10: =O15/O$3 -> 319.19355 | P10: =P15/P$3 -> 219.29032 | Q10: =Q15/Q$3 -> 321.89286 | R10: =R15/R$3 -> 176.93548 | S10: =S15/S$3 -> 178.9 | T10: =T15/T$3 -> 145.19355 | ... X10: =X15/X$3 -> 302 | Z10: =Z15/Z$3 -> 308.45652 | AA10: =AA15/AA$3 -> 236.62222 | AB10: =AB15/AB$3 -> 181.30769 | AC10: =AC15/AC$3 -> 274.73913 | AE10: =AE15/AE$3 -> 272.93407 | AF10: =AF15/AF$3 -> 228.27869 | AH10: =AH15/AH$3 -> 250.54521
H11: Daily Sales Units PY | M11: =M16/M$3 -> 337.6129 | N11: =N16/N$3 -> 330.9 | O11: =O16/O$3 -> 381.93548 | P11: =P16/P$3 -> 363.19355 | Q11: =Q16/Q$3 -> 413.85714 | R11: =R16/R$3 -> 248.3871 | S11: =S16/S$3 -> 264.3 | T11: =T16/T$3 -> 262.22581 | ... X11: =X16/X$3 -> 498.3 | Z11: =Z16/Z$3 -> 350.3587 | AA11: =AA16/AA$3 -> 339.41111 | AB11: =AB16/AB$3 -> 292.91209 | AC11: =AC16/AC$3 -> 441.17391 | AE11: =AE16/AE$3 -> 344.94505 | AF11: =AF16/AF$3 -> 367.44809 | AH11: =AH16/AH$3 -> 356.2274
H12: vs PY | M12: =M10-M11 -> 77.129032 | N12: =N10-N11 -> -143.36667 | O12: =O10-O11 -> -62.741935 | P12: =P10-P11 -> -143.90323 | Q12: =Q10-Q11 -> -91.964286 | R12: =R10-R11 -> -71.451613 | S12: =S10-S11 -> -85.4 | T12: =T10-T11 -> -117.03226 | ... X12: =X10-X11 -> -196.3 | Z12: =Z10-Z11 -> -41.902174 | AA12: =AA10-AA11 -> -102.78889 | AB12: =AB10-AB11 -> -111.6044 | AC12: =AC10-AC11 -> -166.43478 | AE12: =AE10-AE11 -> -72.010989 | AF12: =AF10-AF11 -> -139.1694 | AH12: =AH10-AH11 -> -105.68219
H13: vs PY | J13: % | M13: =M10/M11-1 -> 0.22845404 | N13: =N10/N11-1 -> -0.43326282 | O13: =O10/O11-1 -> -0.16427365 | P13: =P10/P11-1 -> -0.39621636 | Q13: =Q10/Q11-1 -> -0.22221263 | R13: =R10/R11-1 -> -0.28766234 | S13: =S10/S11-1 -> -0.32311767 | T13: =T10/T11-1 -> -0.44630336 | ... X13: =X10/X11-1 -> -0.39393939 | Z13: =Z10/Z11-1 -> -0.11959793 | AA13: =AA10/AA11-1 -> -0.3028448 | AB13: =AB10/AB11-1 -> -0.38101669 | AC13: =AC10/AC11-1 -> -0.37725436 | AE13: =AE10/AE11-1 -> -0.20876075 | AF13: =AF10/AF11-1 -> -0.37874574 | AH13: =AH10/AH11-1 -> -0.29667059
H15: TOTAL Sales Units | M15: =SUMIFS(DATA_2025!$N:$N,DATA_2025!$E:$E,'1.DASHBOARD PERFORMANCE'!M5) -> 12857 | N15: =SUMIFS(DATA_2025!$N:$N,DATA_2025!$E:$E,'1.DASHBOARD PERFORMANCE'!N5) -> 5626 | O15: =SUMIFS(DATA_2025!$N:$N,DATA_2025!$E:$E,'1.DASHBOARD PERFORMANCE'!O5) -> 9895 | P15: =SUMIFS(DATA_2025!$N:$N,DATA_2025!$E:$E,'1.DASHBOARD PERFORMANCE'!P5) -> 6798 | Q15: =SUMIFS(DATA_2025!$N:$N,DATA_2025!$E:$E,'1.DASHBOARD PERFORMANCE'!Q5) -> 9013 | R15: =SUMIFS(DATA_2025!$N:$N,DATA_2025!$E:$E,'1.DASHBOARD PERFORMANCE'!R5) -> 5485 | S15: =SUMIFS(DATA_2025!$N:$N,DATA_2025!$E:$E,'1.DASHBOARD PERFORMANCE'!S5) -> 5367 | T15: =SUMIFS(DATA_2025!$N:$N,DATA_2025!$E:$E,'1.DASHBOARD PERFORMANCE'!T5) -> 4501 | ... X15: =SUMIFS(DATA_2025!$N:$N,DATA_2025!$E:$E,'1.DASHBOARD PERFORMANCE'!X5) -> 9060 | Z15: =SUMIFS(DATA_2025!$N:$N,DATA_2025!$C:$C,Z7) -> 28378 | AA15: =SUMIFS(DATA_2025!$N:$N,DATA_2025!$C:$C,AA7) -> 21296 | AB15: =SUMIFS(DATA_2025!$N:$N,DATA_2025!$C:$C,AB7) -> 16499 | AC15: =SUMIFS(DATA_2025!$N:$N,DATA_2025!$C:$C,AC7) -> 25276 | AE15: =SUMIFS(DATA_2025!$N:$N,DATA_2025!$B:$B,AE7) -> 49674 | AF15: =SUMIFS(DATA_2025!$N:$N,DATA_2025!$B:$B,AF7) -> 41775 | AH15: =SUM(DATA_2025!$N:$N) -> 91449
H16: Total Units PY | M16: =SUMIFS(BENCHMARK_FENTY_2024!$J:$J,BENCHMARK_FENTY_2024!$E:$E,'1.DASHBOARD PERFORMANCE'!M$5) -> 10466 | N16: =SUMIFS(BENCHMARK_FENTY_2024!$J:$J,BENCHMARK_FENTY_2024!$E:$E,'1.DASHBOARD PERFORMANCE'!N$5) -> 9927 | O16: =SUMIFS(BENCHMARK_FENTY_2024!$J:$J,BENCHMARK_FENTY_2024!$E:$E,'1.DASHBOARD PERFORMANCE'!O$5) -> 11840 | P16: =SUMIFS(BENCHMARK_FENTY_2024!$J:$J,BENCHMARK_FENTY_2024!$E:$E,'1.DASHBOARD PERFORMANCE'!P$5) -> 11259 | Q16: =SUMIFS(BENCHMARK_FENTY_2024!$J:$J,BENCHMARK_FENTY_2024!$E:$E,'1.DASHBOARD PERFORMANCE'!Q$5) -> 11588 | R16: =SUMIFS(BENCHMARK_FENTY_2024!$J:$J,BENCHMARK_FENTY_2024!$E:$E,'1.DASHBOARD PERFORMANCE'!R$5) -> 7700 | S16: =SUMIFS(BENCHMARK_FENTY_2024!$J:$J,BENCHMARK_FENTY_2024!$E:$E,'1.DASHBOARD PERFORMANCE'!S$5) -> 7929 | T16: =SUMIFS(BENCHMARK_FENTY_2024!$J:$J,BENCHMARK_FENTY_2024!$E:$E,'1.DASHBOARD PERFORMANCE'!T$5) -> 8129 | ... X16: =SUMIFS(BENCHMARK_FENTY_2024!$J:$J,BENCHMARK_FENTY_2024!$E:$E,'1.DASHBOARD PERFORMANCE'!X$5) -> 14949 | Z16: =SUMIFS(BENCHMARK_FENTY_2024!$J:$J,BENCHMARK_FENTY_2024!$C:$C,'1.DASHBOARD PERFORMANCE'!Z$5) -> 32233 | AA16: =SUMIFS(BENCHMARK_FENTY_2024!$J:$J,BENCHMARK_FENTY_2024!$C:$C,'1.DASHBOARD PERFORMANCE'!AA$5) -> 30547 | AB16: =SUMIFS(BENCHMARK_FENTY_2024!$J:$J,BENCHMARK_FENTY_2024!$C:$C,'1.DASHBOARD PERFORMANCE'!AB$5) -> 26655 | AC16: =SUMIFS(BENCHMARK_FENTY_2024!$J:$J,BENCHMARK_FENTY_2024!$C:$C,'1.DASHBOARD PERFORMANCE'!AC$5) -> 40588 | AE16: =SUMIFS(BENCHMARK_FENTY_2024!$J:$J,BENCHMARK_FENTY_2024!$B:$B,'1.DASHBOARD PERFORMANCE'!AE$5) -> 62780 | AF16: =SUMIFS(BENCHMARK_FENTY_2024!$J:$J,BENCHMARK_FENTY_2024!$B:$B,'1.DASHBOARD PERFORMANCE'!AF$5) -> 67243 | AH16: =SUM(BENCHMARK_FENTY_2024!$J:$J) -> 130023
H17: vs PY | M17: =M15-M16 -> 2391 | N17: =N15-N16 -> -4301 | O17: =O15-O16 -> -1945 | P17: =P15-P16 -> -4461 | Q17: =Q15-Q16 -> -2575 | R17: =R15-R16 -> -2215 | S17: =S15-S16 -> -2562 | T17: =T15-T16 -> -3628 | ... X17: =X15-X16 -> -5889 | Z17: =Z15-Z16 -> -3855 | AA17: =AA15-AA16 -> -9251 | AB17: =AB15-AB16 -> -10156 | AC17: =AC15-AC16 -> -15312 | AE17: =AE15-AE16 -> -13106 | AF17: =AF15-AF16 -> -25468 | AH17: =AH15-AH16 -> -38574
H18: vs PY | J18: % | M18: =M15/M16-1 -> 0.22845404 | N18: =N15/N16-1 -> -0.43326282 | O18: =O15/O16-1 -> -0.16427365 | P18: =P15/P16-1 -> -0.39621636 | Q18: =Q15/Q16-1 -> -0.22221263 | R18: =R15/R16-1 -> -0.28766234 | S18: =S15/S16-1 -> -0.32311767 | T18: =T15/T16-1 -> -0.44630336 | ... X18: =X15/X16-1 -> -0.39393939 | Z18: =Z15/Z16-1 -> -0.11959793 | AA18: =AA15/AA16-1 -> -0.3028448 | AB18: =AB15/AB16-1 -> -0.38101669 | AC18: =AC15/AC16-1 -> -0.37725436 | AE18: =AE15/AE16-1 -> -0.20876075 | AF18: =AF15/AF16-1 -> -0.37874574 | AH18: =AH15/AH16-1 -> -0.29667059
H19: vs Forecast | J19: % | M19: =(M15/SUMIFS(FORECAST_2025!$I:$I,FORECAST_2025!$E:$E,'1.DASHBOARD PERFORMANCE'!M$5))-1 -> 1.2485135 | N19: =(N15/SUMIFS(FORECAST_2025!$I:$I,FORECAST_2025!$E:$E,'1.DASHBOARD PERFORMANCE'!N$5))-1 -> 0.093914058 | O19: =(O15/SUMIFS(FORECAST_2025!$I:$I,FORECAST_2025!$E:$E,'1.DASHBOARD PERFORMANCE'!O$5))-1 -> 0.54609375 | P19: =(P15/SUMIFS(FORECAST_2025!$I:$I,FORECAST_2025!$E:$E,'1.DASHBOARD PERFORMANCE'!P$5))-1 -> 0.11497458 | Q19: =(Q15/SUMIFS(FORECAST_2025!$I:$I,FORECAST_2025!$E:$E,'1.DASHBOARD PERFORMANCE'!Q$5))-1 -> 0.43290938 | R19: =(R15/SUMIFS(FORECAST_2025!$I:$I,FORECAST_2025!$E:$E,'1.DASHBOARD PERFORMANCE'!R$5))-1 -> 0.27085264 | S19: =(S15/SUMIFS(FORECAST_2025!$I:$I,FORECAST_2025!$E:$E,'1.DASHBOARD PERFORMANCE'!S$5))-1 -> 0.17930125 | T19: =(T15/SUMIFS(FORECAST_2025!$I:$I,FORECAST_2025!$E:$E,'1.DASHBOARD PERFORMANCE'!T$5))-1 -> -0.010334213 | ... X19: =(X15/SUMIFS(FORECAST_2025!$I:$I,FORECAST_2025!$E:$E,'1.DASHBOARD PERFORMANCE'!X$5))-1 -> 0.19936458 | Z19: =(Z15/SUMIFS(FORECAST_2025!$I:$I,FORECAST_2025!$C:$C,'1.DASHBOARD PERFORMANCE'!Z$5))-1 -> 0.64405307 | AA19: =(AA15/SUMIFS(FORECAST_2025!$I:$I,FORECAST_2025!$C:$C,'1.DASHBOARD PERFORMANCE'!AA$5))-1 -> 0.27498054 | AB19: =(AB15/SUMIFS(FORECAST_2025!$I:$I,FORECAST_2025!$C:$C,'1.DASHBOARD PERFORMANCE'!AB$5))-1 -> 0.11381894 | AC19: =(AC15/SUMIFS(FORECAST_2025!$I:$I,FORECAST_2025!$C:$C,'1.DASHBOARD PERFORMANCE'!AC$5))-1 -> 0.20574345 | AE19: =(AE15/SUMIFS(FORECAST_2025!$I:$I,FORECAST_2025!$B:$B,'1.DASHBOARD PERFORMANCE'!AE$5))-1 -> 0.46254858 | AF19: =(AF15/SUMIFS(FORECAST_2025!$I:$I,FORECAST_2025!$B:$B,'1.DASHBOARD PERFORMANCE'!AF$5))-1 -> 0.16768225 | AH19: =(AH15/SUM(FORECAST_2025!$I:$I))-1 -> 0.31128477
H21: Revenue | J21: € | M21: =SUMIFS(DATA_2025!$Q:$Q,DATA_2025!$E:$E,M5) -> 410565.3 | N21: =SUMIFS(DATA_2025!$Q:$Q,DATA_2025!$E:$E,N5) -> 177813.2 | O21: =SUMIFS(DATA_2025!$Q:$Q,DATA_2025!$E:$E,O5) -> 300089.1 | P21: =SUMIFS(DATA_2025!$Q:$Q,DATA_2025!$E:$E,P5) -> 214436.3 | Q21: =SUMIFS(DATA_2025!$Q:$Q,DATA_2025!$E:$E,Q5) -> 282888.5 | R21: =SUMIFS(DATA_2025!$Q:$Q,DATA_2025!$E:$E,R5) -> 161365.7 | S21: =SUMIFS(DATA_2025!$Q:$Q,DATA_2025!$E:$E,S5) -> 159674.2 | T21: =SUMIFS(DATA_2025!$Q:$Q,DATA_2025!$E:$E,T5) -> 140989.5 | ... X21: =SUMIFS(DATA_2025!$Q:$Q,DATA_2025!$E:$E,X5) -> 275716.2 | Z21: =SUMIFS(DATA_2025!$Q:$Q,DATA_2025!$C:$C,Z5) -> 888467.6 | AA21: =SUMIFS(DATA_2025!$Q:$Q,DATA_2025!$C:$C,AA5) -> 658690.5 | AB21: =SUMIFS(DATA_2025!$Q:$Q,DATA_2025!$C:$C,AB5) -> 507970.2 | AC21: =SUMIFS(DATA_2025!$Q:$Q,DATA_2025!$C:$C,AC5) -> 737482.1 | AE21: =SUM(Z21:AA21) -> 1547158.1 | AF21: =SUM(AB21:AC21) -> 1245452.3 | AH21: =SUM(DATA_2025!Q:Q) -> 2792610.4
H22: Revenue PY | J22: € | M22: =SUMIFS(BENCHMARK_FENTY_2024!$K:$K,BENCHMARK_FENTY_2024!$E:$E,'1.DASHBOARD PERFORMANCE'!M$5) -> 397708 | N22: =SUMIFS(BENCHMARK_FENTY_2024!$K:$K,BENCHMARK_FENTY_2024!$E:$E,'1.DASHBOARD PERFORMANCE'!N$5) -> 377226 | O22: =SUMIFS(BENCHMARK_FENTY_2024!$K:$K,BENCHMARK_FENTY_2024!$E:$E,'1.DASHBOARD PERFORMANCE'!O$5) -> 449920 | P22: =SUMIFS(BENCHMARK_FENTY_2024!$K:$K,BENCHMARK_FENTY_2024!$E:$E,'1.DASHBOARD PERFORMANCE'!P$5) -> 427842 | Q22: =SUMIFS(BENCHMARK_FENTY_2024!$K:$K,BENCHMARK_FENTY_2024!$E:$E,'1.DASHBOARD PERFORMANCE'!Q$5) -> 440344 | R22: =SUMIFS(BENCHMARK_FENTY_2024!$K:$K,BENCHMARK_FENTY_2024!$E:$E,'1.DASHBOARD PERFORMANCE'!R$5) -> 292600 | S22: =SUMIFS(BENCHMARK_FENTY_2024!$K:$K,BENCHMARK_FENTY_2024!$E:$E,'1.DASHBOARD PERFORMANCE'!S$5) -> 301302 | T22: =SUMIFS(BENCHMARK_FENTY_2024!$K:$K,BENCHMARK_FENTY_2024!$E:$E,'1.DASHBOARD PERFORMANCE'!T$5) -> 308902 | ... X22: =SUMIFS(BENCHMARK_FENTY_2024!$K:$K,BENCHMARK_FENTY_2024!$E:$E,'1.DASHBOARD PERFORMANCE'!X$5) -> 568062 | Z22: =SUMIFS(BENCHMARK_FENTY_2024!$K:$K,BENCHMARK_FENTY_2024!$C:$C,'1.DASHBOARD PERFORMANCE'!Z$5) -> 1224854 | AA22: =SUMIFS(BENCHMARK_FENTY_2024!$K:$K,BENCHMARK_FENTY_2024!$C:$C,'1.DASHBOARD PERFORMANCE'!AA$5) -> 1160786 | AB22: =SUMIFS(BENCHMARK_FENTY_2024!$K:$K,BENCHMARK_FENTY_2024!$C:$C,'1.DASHBOARD PERFORMANCE'!AB$5) -> 1012890 | AC22: =SUMIFS(BENCHMARK_FENTY_2024!$K:$K,BENCHMARK_FENTY_2024!$C:$C,'1.DASHBOARD PERFORMANCE'!AC$5) -> 1542344 | AE22: =SUMIFS(BENCHMARK_FENTY_2024!$K:$K,BENCHMARK_FENTY_2024!$B:$B,'1.DASHBOARD PERFORMANCE'!AE$5) -> 2385640 | AF22: =SUMIFS(BENCHMARK_FENTY_2024!$K:$K,BENCHMARK_FENTY_2024!$B:$B,'1.DASHBOARD PERFORMANCE'!AF$5) -> 2555234 | AH22: =SUM(BENCHMARK_FENTY_2024!$K:$K) -> 4940874
H23: vs PY | J23: € | M23: =M21-M22 -> 12857.3 | N23: =N21-N22 -> -199412.8 | O23: =O21-O22 -> -149830.9 | P23: =P21-P22 -> -213405.7 | Q23: =Q21-Q22 -> -157455.5 | R23: =R21-R22 -> -131234.3 | S23: =S21-S22 -> -141627.8 | T23: =T21-T22 -> -167912.5 | ... X23: =X21-X22 -> -292345.8 | Z23: =Z21-Z22 -> -336386.4 | AA23: =AA21-AA22 -> -502095.5 | AB23: =AB21-AB22 -> -504919.8 | AC23: =AC21-AC22 -> -804861.9 | AE23: =AE21-AE22 -> -838481.9 | AF23: =AF21-AF22 -> -1309781.7 | AH23: =AH21-AH22 -> -2148263.6
H24: vs PY | J24: % | M24: =M21/M22-1 -> 0.032328492 | N24: =N21/N22-1 -> -0.52862952 | O24: =O21/O22-1 -> -0.33301676 | P24: =P21/P22-1 -> -0.49879558 | Q24: =Q21/Q22-1 -> -0.35757385 | R24: =R21/R22-1 -> -0.44851094 | S24: =S21/S22-1 -> -0.47005264 | T24: =T21/T22-1 -> -0.54357855 | ... X24: =X21/X22-1 -> -0.51463713 | Z24: =Z21/Z22-1 -> -0.27463387 | AA24: =AA21/AA22-1 -> -0.43254786 | AB24: =AB21/AB22-1 -> -0.49849421 | AC24: =AC21/AC22-1 -> -0.52184331 | AE24: =AE21/AE22-1 -> -0.35147042 | AF24: =AF21/AF22-1 -> -0.51258777 | AH24: =AH21/AH22-1 -> -0.43479425
H25: vs Forecast | J25: % | M25: =(M21/SUMIFS(FORECAST_2025!$J:$J,FORECAST_2025!$E:$E,'1.DASHBOARD PERFORMANCE'!M$5))-1 -> 1.2947531 | N25: =(N21/SUMIFS(FORECAST_2025!$J:$J,FORECAST_2025!$E:$E,'1.DASHBOARD PERFORMANCE'!N$5))-1 -> 0.10487176 | O25: =(O21/SUMIFS(FORECAST_2025!$J:$J,FORECAST_2025!$E:$E,'1.DASHBOARD PERFORMANCE'!O$5))-1 -> 0.49853562 | P25: =(P21/SUMIFS(FORECAST_2025!$J:$J,FORECAST_2025!$E:$E,'1.DASHBOARD PERFORMANCE'!P$5))-1 -> 0.12408323 | Q25: =(Q21/SUMIFS(FORECAST_2025!$J:$J,FORECAST_2025!$E:$E,'1.DASHBOARD PERFORMANCE'!Q$5))-1 -> 0.43737583 | R25: =(R21/SUMIFS(FORECAST_2025!$J:$J,FORECAST_2025!$E:$E,'1.DASHBOARD PERFORMANCE'!R$5))-1 -> 0.19475632 | S25: =(S21/SUMIFS(FORECAST_2025!$J:$J,FORECAST_2025!$E:$E,'1.DASHBOARD PERFORMANCE'!S$5))-1 -> 0.12111627 | T25: =(T21/SUMIFS(FORECAST_2025!$J:$J,FORECAST_2025!$E:$E,'1.DASHBOARD PERFORMANCE'!T$5))-1 -> -0.0092936581 | ... X25: =(X21/SUMIFS(FORECAST_2025!$J:$J,FORECAST_2025!$E:$E,'1.DASHBOARD PERFORMANCE'!X$5))-1 -> 0.16659594 | Z25: =(Z21/SUMIFS(FORECAST_2025!$J:$J,FORECAST_2025!$C:$C,'1.DASHBOARD PERFORMANCE'!Z$5))-1 -> 0.6449896 | AA25: =(AA21/SUMIFS(FORECAST_2025!$J:$J,FORECAST_2025!$C:$C,'1.DASHBOARD PERFORMANCE'!AA$5))-1 -> 0.26032339 | AB25: =(AB21/SUMIFS(FORECAST_2025!$J:$J,FORECAST_2025!$C:$C,'1.DASHBOARD PERFORMANCE'!AB$5))-1 -> 0.095896339 | AC25: =(AC21/SUMIFS(FORECAST_2025!$J:$J,FORECAST_2025!$C:$C,'1.DASHBOARD PERFORMANCE'!AC$5))-1 -> 0.12438346 | AE25: =(AE21/SUMIFS(FORECAST_2025!$J:$J,FORECAST_2025!$B:$B,'1.DASHBOARD PERFORMANCE'!AE$5))-1 -> 0.45581804 | AF25: =(AF21/SUMIFS(FORECAST_2025!$J:$J,FORECAST_2025!$B:$B,'1.DASHBOARD PERFORMANCE'!AF$5))-1 -> 0.11258774 | AH25: =(AH21/SUM(FORECAST_2025!$J:$J))-1 -> 0.27974547
H27: Average Selling Price | J27: € | M27: =SUMIFS(DATA_2025!$Q:$Q,DATA_2025!$E:$E, M$5)/SUMIFS(DATA_2025!$N:$N,DATA_2025!$E:$E, M$5) -> 31.933211 | N27: =SUMIFS(DATA_2025!$Q:$Q,DATA_2025!$E:$E, N$5)/SUMIFS(DATA_2025!$N:$N,DATA_2025!$E:$E, N$5) -> 31.605617 | O27: =SUMIFS(DATA_2025!$Q:$Q,DATA_2025!$E:$E, O$5)/SUMIFS(DATA_2025!$N:$N,DATA_2025!$E:$E, O$5) -> 30.327347 | P27: =SUMIFS(DATA_2025!$Q:$Q,DATA_2025!$E:$E, P$5)/SUMIFS(DATA_2025!$N:$N,DATA_2025!$E:$E, P$5) -> 31.544028 | Q27: =SUMIFS(DATA_2025!$Q:$Q,DATA_2025!$E:$E, Q$5)/SUMIFS(DATA_2025!$N:$N,DATA_2025!$E:$E, Q$5) -> 31.386719 | R27: =SUMIFS(DATA_2025!$Q:$Q,DATA_2025!$E:$E, R$5)/SUMIFS(DATA_2025!$N:$N,DATA_2025!$E:$E, R$5) -> 29.419453 | S27: =SUMIFS(DATA_2025!$Q:$Q,DATA_2025!$E:$E, S$5)/SUMIFS(DATA_2025!$N:$N,DATA_2025!$E:$E, S$5) -> 29.751109 | T27: =SUMIFS(DATA_2025!$Q:$Q,DATA_2025!$E:$E, T$5)/SUMIFS(DATA_2025!$N:$N,DATA_2025!$E:$E, T$5) -> 31.324039 | ... X27: =SUMIFS(DATA_2025!$Q:$Q,DATA_2025!$E:$E, X$5)/SUMIFS(DATA_2025!$N:$N,DATA_2025!$E:$E, X$5) -> 30.432252 | Z27: =SUMIFS(DATA_2025!$Q:$Q,DATA_2025!$C:$C, Z$5)/SUMIFS(DATA_2025!$N:$N,DATA_2025!$C:$C, Z$5) -> 31.308323 | AA27: =SUMIFS(DATA_2025!$Q:$Q,DATA_2025!$C:$C, AA$5)/SUMIFS(DATA_2025!$N:$N,DATA_2025!$C:$C, AA$5) -> 30.930245 | AB27: =SUMIFS(DATA_2025!$Q:$Q,DATA_2025!$C:$C, AB$5)/SUMIFS(DATA_2025!$N:$N,DATA_2025!$C:$C, AB$5) -> 30.787939 | AC27: =SUMIFS(DATA_2025!$Q:$Q,DATA_2025!$C:$C, AC$5)/SUMIFS(DATA_2025!$N:$N,DATA_2025!$C:$C, AC$5) -> 29.177168 | AE27: =SUMIFS(DATA_2025!$Q:$Q,DATA_2025!$B:$B, AE$5)/SUMIFS(DATA_2025!$N:$N,DATA_2025!$B:$B, AE$5) -> 31.146235 | AF27: =SUMIFS(DATA_2025!$Q:$Q,DATA_2025!$B:$B, AF$5)/SUMIFS(DATA_2025!$N:$N,DATA_2025!$B:$B, AF$5) -> 29.813341 | AH27: =SUM(DATA_2025!$Q:$Q)/SUM(DATA_2025!$N:$N) -> 30.537353
H28: ASP PY | J28: € | M28: =SUMIFS(BENCHMARK_FENTY_2024!$K:$K,BENCHMARK_FENTY_2024!$E:$E,'1.DASHBOARD PERFORMANCE'!M$5)/SUMIFS(BENCHMARK_FENTY_2024!$J:$J,BENCHMARK_FENTY_2024!$E:$E,'1.DASHBOARD PERFORMANCE'!M$5) -> 38 | N28: =SUMIFS(BENCHMARK_FENTY_2024!$K:$K,BENCHMARK_FENTY_2024!$E:$E,'1.DASHBOARD PERFORMANCE'!N$5)/SUMIFS(BENCHMARK_FENTY_2024!$J:$J,BENCHMARK_FENTY_2024!$E:$E,'1.DASHBOARD PERFORMANCE'!N$5) -> 38 | O28: =SUMIFS(BENCHMARK_FENTY_2024!$K:$K,BENCHMARK_FENTY_2024!$E:$E,'1.DASHBOARD PERFORMANCE'!O$5)/SUMIFS(BENCHMARK_FENTY_2024!$J:$J,BENCHMARK_FENTY_2024!$E:$E,'1.DASHBOARD PERFORMANCE'!O$5) -> 38 | P28: =SUMIFS(BENCHMARK_FENTY_2024!$K:$K,BENCHMARK_FENTY_2024!$E:$E,'1.DASHBOARD PERFORMANCE'!P$5)/SUMIFS(BENCHMARK_FENTY_2024!$J:$J,BENCHMARK_FENTY_2024!$E:$E,'1.DASHBOARD PERFORMANCE'!P$5) -> 38 | Q28: =SUMIFS(BENCHMARK_FENTY_2024!$K:$K,BENCHMARK_FENTY_2024!$E:$E,'1.DASHBOARD PERFORMANCE'!Q$5)/SUMIFS(BENCHMARK_FENTY_2024!$J:$J,BENCHMARK_FENTY_2024!$E:$E,'1.DASHBOARD PERFORMANCE'!Q$5) -> 38 | R28: =SUMIFS(BENCHMARK_FENTY_2024!$K:$K,BENCHMARK_FENTY_2024!$E:$E,'1.DASHBOARD PERFORMANCE'!R$5)/SUMIFS(BENCHMARK_FENTY_2024!$J:$J,BENCHMARK_FENTY_2024!$E:$E,'1.DASHBOARD PERFORMANCE'!R$5) -> 38 | S28: =SUMIFS(BENCHMARK_FENTY_2024!$K:$K,BENCHMARK_FENTY_2024!$E:$E,'1.DASHBOARD PERFORMANCE'!S$5)/SUMIFS(BENCHMARK_FENTY_2024!$J:$J,BENCHMARK_FENTY_2024!$E:$E,'1.DASHBOARD PERFORMANCE'!S$5) -> 38 | T28: =SUMIFS(BENCHMARK_FENTY_2024!$K:$K,BENCHMARK_FENTY_2024!$E:$E,'1.DASHBOARD PERFORMANCE'!T$5)/SUMIFS(BENCHMARK_FENTY_2024!$J:$J,BENCHMARK_FENTY_2024!$E:$E,'1.DASHBOARD PERFORMANCE'!T$5) -> 38 | ... X28: =SUMIFS(BENCHMARK_FENTY_2024!$K:$K,BENCHMARK_FENTY_2024!$E:$E,'1.DASHBOARD PERFORMANCE'!X$5)/SUMIFS(BENCHMARK_FENTY_2024!$J:$J,BENCHMARK_FENTY_2024!$E:$E,'1.DASHBOARD PERFORMANCE'!X$5) -> 38 | Z28: =SUMIFS(BENCHMARK_FENTY_2024!$K:$K,BENCHMARK_FENTY_2024!$C:$C,'1.DASHBOARD PERFORMANCE'!Z$5)/SUMIFS(BENCHMARK_FENTY_2024!$J:$J,BENCHMARK_FENTY_2024!$C:$C,'1.DASHBOARD PERFORMANCE'!Z$5) -> 38 | AA28: =SUMIFS(BENCHMARK_FENTY_2024!$K:$K,BENCHMARK_FENTY_2024!$C:$C,'1.DASHBOARD PERFORMANCE'!AA$5)/SUMIFS(BENCHMARK_FENTY_2024!$J:$J,BENCHMARK_FENTY_2024!$C:$C,'1.DASHBOARD PERFORMANCE'!AA$5) -> 38 | AB28: =SUMIFS(BENCHMARK_FENTY_2024!$K:$K,BENCHMARK_FENTY_2024!$C:$C,'1.DASHBOARD PERFORMANCE'!AB$5)/SUMIFS(BENCHMARK_FENTY_2024!$J:$J,BENCHMARK_FENTY_2024!$C:$C,'1.DASHBOARD PERFORMANCE'!AB$5) -> 38 | AC28: =SUMIFS(BENCHMARK_FENTY_2024!$K:$K,BENCHMARK_FENTY_2024!$C:$C,'1.DASHBOARD PERFORMANCE'!AC$5)/SUMIFS(BENCHMARK_FENTY_2024!$J:$J,BENCHMARK_FENTY_2024!$C:$C,'1.DASHBOARD PERFORMANCE'!AC$5) -> 38 | AE28: =SUMIFS(BENCHMARK_FENTY_2024!$K:$K,BENCHMARK_FENTY_2024!$B:$B,'1.DASHBOARD PERFORMANCE'!AE$5)/SUMIFS(BENCHMARK_FENTY_2024!$J:$J,BENCHMARK_FENTY_2024!$B:$B,'1.DASHBOARD PERFORMANCE'!AE$5) -> 38 | AF28: =SUMIFS(BENCHMARK_FENTY_2024!$K:$K,BENCHMARK_FENTY_2024!$B:$B,'1.DASHBOARD PERFORMANCE'!AF$5)/SUMIFS(BENCHMARK_FENTY_2024!$J:$J,BENCHMARK_FENTY_2024!$B:$B,'1.DASHBOARD PERFORMANCE'!AF$5) -> 38 | AH28: =SUM(BENCHMARK_FENTY_2024!$K:$K)/SUM(BENCHMARK_FENTY_2024!$J:$J) -> 38
H29: vs PY | J29: € | M29: =M27-M28 -> -6.0667885 | N29: =N27-N28 -> -6.3943832 | O29: =O27-O28 -> -7.6726529 | P29: =P27-P28 -> -6.4559723 | Q29: =Q27-Q28 -> -6.6132808 | R29: =R27-R28 -> -8.5805469 | S29: =S27-S28 -> -8.2488914 | T29: =T27-T28 -> -6.6759609 | ... X29: =X27-X28 -> -7.5677483 | Z29: =Z27-Z28 -> -6.6916767 | AA29: =AA27-AA28 -> -7.0697549 | AB29: =AB27-AB28 -> -7.2120613 | AC29: =AC27-AC28 -> -8.8228319 | AE29: =AE27-AE28 -> -6.8537645 | AF29: =AF27-AF28 -> -8.1866595 | AH29: =AH27-AH28 -> -7.4626469
H30: vs PY | J30: % | M30: =M27/M28-1 -> -0.15965233 | N30: =N27/N28-1 -> -0.16827324 | O30: =O27/O28-1 -> -0.20191192 | P30: =P27/P28-1 -> -0.16989401 | Q30: =Q27/Q28-1 -> -0.17403371 | R30: =R27/R28-1 -> -0.22580387 | S30: =S27/S28-1 -> -0.21707609 | T30: =T27/T28-1 -> -0.17568318 | ... X30: =X27/X28-1 -> -0.19915127 | Z30: =Z27/Z28-1 -> -0.17609675 | AA30: =AA27/AA28-1 -> -0.18604618 | AB30: =AB27/AB28-1 -> -0.18979109 | AC30: =AC27/AC28-1 -> -0.23217979 | AE30: =AE27/AE28-1 -> -0.18036222 | AF30: =AF27/AF28-1 -> -0.21543841 | AH30: =AH27/AH28-1 -> -0.19638545
H31: Forecast | J31: € | M31: =SUMIFS(FORECAST_2025!$J:$J,FORECAST_2025!$E:$E,'1.DASHBOARD PERFORMANCE'!M$5)/SUMIFS(FORECAST_2025!$I:$I,FORECAST_2025!$E:$E,'1.DASHBOARD PERFORMANCE'!M$5) -> 31.289752 | N31: =SUMIFS(FORECAST_2025!$J:$J,FORECAST_2025!$E:$E,'1.DASHBOARD PERFORMANCE'!N$5)/SUMIFS(FORECAST_2025!$I:$I,FORECAST_2025!$E:$E,'1.DASHBOARD PERFORMANCE'!N$5) -> 31.292164 | O31: =SUMIFS(FORECAST_2025!$J:$J,FORECAST_2025!$E:$E,'1.DASHBOARD PERFORMANCE'!O$5)/SUMIFS(FORECAST_2025!$I:$I,FORECAST_2025!$E:$E,'1.DASHBOARD PERFORMANCE'!O$5) -> 31.289828 | P31: =SUMIFS(FORECAST_2025!$J:$J,FORECAST_2025!$E:$E,'1.DASHBOARD PERFORMANCE'!P$5)/SUMIFS(FORECAST_2025!$I:$I,FORECAST_2025!$E:$E,'1.DASHBOARD PERFORMANCE'!P$5) -> 31.288421 | Q31: =SUMIFS(FORECAST_2025!$J:$J,FORECAST_2025!$E:$E,'1.DASHBOARD PERFORMANCE'!Q$5)/SUMIFS(FORECAST_2025!$I:$I,FORECAST_2025!$E:$E,'1.DASHBOARD PERFORMANCE'!Q$5) -> 31.289189 | R31: =SUMIFS(FORECAST_2025!$J:$J,FORECAST_2025!$E:$E,'1.DASHBOARD PERFORMANCE'!R$5)/SUMIFS(FORECAST_2025!$I:$I,FORECAST_2025!$E:$E,'1.DASHBOARD PERFORMANCE'!R$5) -> 31.293234 | S31: =SUMIFS(FORECAST_2025!$J:$J,FORECAST_2025!$E:$E,'1.DASHBOARD PERFORMANCE'!S$5)/SUMIFS(FORECAST_2025!$I:$I,FORECAST_2025!$E:$E,'1.DASHBOARD PERFORMANCE'!S$5) -> 31.295166 | T31: =SUMIFS(FORECAST_2025!$J:$J,FORECAST_2025!$E:$E,'1.DASHBOARD PERFORMANCE'!T$5)/SUMIFS(FORECAST_2025!$I:$I,FORECAST_2025!$E:$E,'1.DASHBOARD PERFORMANCE'!T$5) -> 31.291139 | ... X31: =SUMIFS(FORECAST_2025!$J:$J,FORECAST_2025!$E:$E,'1.DASHBOARD PERFORMANCE'!X$5)/SUMIFS(FORECAST_2025!$I:$I,FORECAST_2025!$E:$E,'1.DASHBOARD PERFORMANCE'!X$5) -> 31.287066 | Z31: =SUMIFS(FORECAST_2025!$J:$J,FORECAST_2025!$C:$C,'1.DASHBOARD PERFORMANCE'!Z$5)/SUMIFS(FORECAST_2025!$I:$I,FORECAST_2025!$C:$C,'1.DASHBOARD PERFORMANCE'!Z$5) -> 31.290499 | AA31: =SUMIFS(FORECAST_2025!$J:$J,FORECAST_2025!$C:$C,'1.DASHBOARD PERFORMANCE'!AA$5)/SUMIFS(FORECAST_2025!$I:$I,FORECAST_2025!$C:$C,'1.DASHBOARD PERFORMANCE'!AA$5) -> 31.289954 | AB31: =SUMIFS(FORECAST_2025!$J:$J,FORECAST_2025!$C:$C,'1.DASHBOARD PERFORMANCE'!AB$5)/SUMIFS(FORECAST_2025!$I:$I,FORECAST_2025!$C:$C,'1.DASHBOARD PERFORMANCE'!AB$5) -> 31.291453 | AC31: =SUMIFS(FORECAST_2025!$J:$J,FORECAST_2025!$C:$C,'1.DASHBOARD PERFORMANCE'!AC$5)/SUMIFS(FORECAST_2025!$I:$I,FORECAST_2025!$C:$C,'1.DASHBOARD PERFORMANCE'!AC$5) -> 31.288418 | AE31: =SUMIFS(FORECAST_2025!$J:$J,FORECAST_2025!$B:$B,'1.DASHBOARD PERFORMANCE'!AE$5)/SUMIFS(FORECAST_2025!$I:$I,FORECAST_2025!$B:$B,'1.DASHBOARD PERFORMANCE'!AE$5) -> 31.290231 | AF31: =SUMIFS(FORECAST_2025!$J:$J,FORECAST_2025!$B:$B,'1.DASHBOARD PERFORMANCE'!AF$5)/SUMIFS(FORECAST_2025!$I:$I,FORECAST_2025!$B:$B,'1.DASHBOARD PERFORMANCE'!AF$5) -> 31.289675 | AH31: =SUM(FORECAST_2025!$J:$J)/SUM(FORECAST_2025!$I:$I) -> 31.289946
H32: vs Forecast | J32: % | M32: =M27/M31-1 -> 0.020564555 | N32: =N27/N31-1 -> 0.01001697 | O32: =O27/O31-1 -> -0.030760188 | P32: =P27/P31-1 -> 0.0081693839 | Q32: =Q27/Q31-1 -> 0.0031170509 | R32: =R27/R31-1 -> -0.059878164 | S32: =S27/S31-1 -> -0.049338523 | T32: =T27/T31-1 -> 0.0010514203 | ... X32: =X27/X31-1 -> -0.027321667 | Z32: =Z27/Z31-1 -> 0.00056964693 | AA32: =AA27/AA31-1 -> -0.011495983 | AB32: =AB27/AB31-1 -> -0.016091128 | AC32: =AC27/AC31-1 -> -0.067477034 | AE32: =AE27/AE31-1 -> -0.0046019276 | AF32: =AF27/AF31-1 -> -0.047182789 | AH32: =AH27/AH31-1 -> -0.024052214
H34: Average Discount | J34: % | M34: =(SUMIFS(DATA_2025!$P:$P,DATA_2025!$E:$E,'1.DASHBOARD PERFORMANCE'!M$5)/SUMIFS(DATA_2025!$N:$N,DATA_2025!$E:$E,'1.DASHBOARD PERFORMANCE'!M5))/100 -> 0 | N34: =(SUMIFS(DATA_2025!$P:$P,DATA_2025!$E:$E,'1.DASHBOARD PERFORMANCE'!N$5)/SUMIFS(DATA_2025!$N:$N,DATA_2025!$E:$E,'1.DASHBOARD PERFORMANCE'!N5))/100 -> 0 | O34: =(SUMIFS(DATA_2025!$P:$P,DATA_2025!$E:$E,'1.DASHBOARD PERFORMANCE'!O$5)/SUMIFS(DATA_2025!$N:$N,DATA_2025!$E:$E,'1.DASHBOARD PERFORMANCE'!O5))/100 -> 0.066867105 | P34: =(SUMIFS(DATA_2025!$P:$P,DATA_2025!$E:$E,'1.DASHBOARD PERFORMANCE'!P$5)/SUMIFS(DATA_2025!$N:$N,DATA_2025!$E:$E,'1.DASHBOARD PERFORMANCE'!P5))/100 -> 0 | Q34: =(SUMIFS(DATA_2025!$P:$P,DATA_2025!$E:$E,'1.DASHBOARD PERFORMANCE'!Q$5)/SUMIFS(DATA_2025!$N:$N,DATA_2025!$E:$E,'1.DASHBOARD PERFORMANCE'!Q5))/100 -> 0 | R34: =(SUMIFS(DATA_2025!$P:$P,DATA_2025!$E:$E,'1.DASHBOARD PERFORMANCE'!R$5)/SUMIFS(DATA_2025!$N:$N,DATA_2025!$E:$E,'1.DASHBOARD PERFORMANCE'!R5))/100 -> 0.095132179 | S34: =(SUMIFS(DATA_2025!$P:$P,DATA_2025!$E:$E,'1.DASHBOARD PERFORMANCE'!S$5)/SUMIFS(DATA_2025!$N:$N,DATA_2025!$E:$E,'1.DASHBOARD PERFORMANCE'!S5))/100 -> 0.077957891 | T34: =(SUMIFS(DATA_2025!$P:$P,DATA_2025!$E:$E,'1.DASHBOARD PERFORMANCE'!T$5)/SUMIFS(DATA_2025!$N:$N,DATA_2025!$E:$E,'1.DASHBOARD PERFORMANCE'!T5))/100 -> 0 | ... X34: =(SUMIFS(DATA_2025!$P:$P,DATA_2025!$E:$E,'1.DASHBOARD PERFORMANCE'!X$5)/SUMIFS(DATA_2025!$N:$N,DATA_2025!$E:$E,'1.DASHBOARD PERFORMANCE'!X5))/100 -> 0.023813466 | Z34: =(SUMIFS(DATA_2025!$P:$P,DATA_2025!$C:$C,'1.DASHBOARD PERFORMANCE'!Z$5)/SUMIFS(DATA_2025!$N:$N,DATA_2025!$C:$C,'1.DASHBOARD PERFORMANCE'!Z5))/100 -> 0.023315597 | AA34: =(SUMIFS(DATA_2025!$P:$P,DATA_2025!$C:$C,'1.DASHBOARD PERFORMANCE'!AA$5)/SUMIFS(DATA_2025!$N:$N,DATA_2025!$C:$C,'1.DASHBOARD PERFORMANCE'!AA5))/100 -> 0.024502254 | AB34: =(SUMIFS(DATA_2025!$P:$P,DATA_2025!$C:$C,'1.DASHBOARD PERFORMANCE'!AB$5)/SUMIFS(DATA_2025!$N:$N,DATA_2025!$C:$C,'1.DASHBOARD PERFORMANCE'!AB5))/100 -> 0.025359113 | AC34: =(SUMIFS(DATA_2025!$P:$P,DATA_2025!$C:$C,'1.DASHBOARD PERFORMANCE'!AC$5)/SUMIFS(DATA_2025!$N:$N,DATA_2025!$C:$C,'1.DASHBOARD PERFORMANCE'!AC5))/100 -> 0.080635781 | AE34: =(SUMIFS(DATA_2025!$P:$P,DATA_2025!$B:$B,'1.DASHBOARD PERFORMANCE'!AE$5)/SUMIFS(DATA_2025!$N:$N,DATA_2025!$B:$B,'1.DASHBOARD PERFORMANCE'!AE5))/100 -> 0.023824335 | AF34: =(SUMIFS(DATA_2025!$P:$P,DATA_2025!$B:$B,'1.DASHBOARD PERFORMANCE'!AF$5)/SUMIFS(DATA_2025!$N:$N,DATA_2025!$B:$B,'1.DASHBOARD PERFORMANCE'!AF5))/100 -> 0.058804309 | AH34: =(SUM(DATA_2025!$P:$P)/SUM(DATA_2025!$N:$N))/100 -> 0.039803606
F37: PROFITABILITY
H38: Gross Margin | J38: € | M38: =SUMIFS(DATA_2025!$T:$T,DATA_2025!$E:$E,M$5) -> 294852.3 | N38: =SUMIFS(DATA_2025!$T:$T,DATA_2025!$E:$E,N$5) -> 127179.2 | O38: =SUMIFS(DATA_2025!$T:$T,DATA_2025!$E:$E,O$5) -> 211034.1 | P38: =SUMIFS(DATA_2025!$T:$T,DATA_2025!$E:$E,P$5) -> 153254.3 | Q38: =SUMIFS(DATA_2025!$T:$T,DATA_2025!$E:$E,Q$5) -> 201771.5 | R38: =SUMIFS(DATA_2025!$T:$T,DATA_2025!$E:$E,R$5) -> 112000.7 | S38: =SUMIFS(DATA_2025!$T:$T,DATA_2025!$E:$E,S$5) -> 111371.2 | T38: =SUMIFS(DATA_2025!$T:$T,DATA_2025!$E:$E,T$5) -> 100480.5 | ... X38: =SUMIFS(DATA_2025!$T:$T,DATA_2025!$E:$E,X$5) -> 194176.2 | Z38: =SUMIFS(DATA_2025!$T:$T,DATA_2025!$C:$C,Z$5) -> 633065.6 | AA38: =SUMIFS(DATA_2025!$T:$T,DATA_2025!$C:$C,AA$5) -> 467026.5 | AB38: =SUMIFS(DATA_2025!$T:$T,DATA_2025!$C:$C,AB$5) -> 359479.2 | AC38: =SUMIFS(DATA_2025!$T:$T,DATA_2025!$C:$C,AC$5) -> 509998.1 | AE38: =SUMIFS(DATA_2025!$T:$T,DATA_2025!$B:$B,AE$5) -> 1100092.1 | AF38: =SUMIFS(DATA_2025!$T:$T,DATA_2025!$B:$B,AF$5) -> 869477.3 | AH38: =SUM(AE38:AF38) -> 1969569.4
H39: Gross Margin PY | M39: =(SUMIFS(BENCHMARK_FENTY_2024!$J:$J,BENCHMARK_FENTY_2024!$E:$E,M$5)*38-SUMIFS(BENCHMARK_FENTY_2024!$J:$J,BENCHMARK_FENTY_2024!$E:$E,M$5)*10) -> 293048 | N39: =(SUMIFS(BENCHMARK_FENTY_2024!$J:$J,BENCHMARK_FENTY_2024!$E:$E,N$5)*38-SUMIFS(BENCHMARK_FENTY_2024!$J:$J,BENCHMARK_FENTY_2024!$E:$E,N$5)*10) -> 277956 | O39: =(SUMIFS(BENCHMARK_FENTY_2024!$J:$J,BENCHMARK_FENTY_2024!$E:$E,O$5)*38-SUMIFS(BENCHMARK_FENTY_2024!$J:$J,BENCHMARK_FENTY_2024!$E:$E,O$5)*10) -> 331520 | P39: =(SUMIFS(BENCHMARK_FENTY_2024!$J:$J,BENCHMARK_FENTY_2024!$E:$E,P$5)*38-SUMIFS(BENCHMARK_FENTY_2024!$J:$J,BENCHMARK_FENTY_2024!$E:$E,P$5)*10) -> 315252 | Q39: =(SUMIFS(BENCHMARK_FENTY_2024!$J:$J,BENCHMARK_FENTY_2024!$E:$E,Q$5)*38-SUMIFS(BENCHMARK_FENTY_2024!$J:$J,BENCHMARK_FENTY_2024!$E:$E,Q$5)*10) -> 324464 | R39: =(SUMIFS(BENCHMARK_FENTY_2024!$J:$J,BENCHMARK_FENTY_2024!$E:$E,R$5)*38-SUMIFS(BENCHMARK_FENTY_2024!$J:$J,BENCHMARK_FENTY_2024!$E:$E,R$5)*10) -> 215600 | S39: =(SUMIFS(BENCHMARK_FENTY_2024!$J:$J,BENCHMARK_FENTY_2024!$E:$E,S$5)*38-SUMIFS(BENCHMARK_FENTY_2024!$J:$J,BENCHMARK_FENTY_2024!$E:$E,S$5)*10) -> 222012 | T39: =(SUMIFS(BENCHMARK_FENTY_2024!$J:$J,BENCHMARK_FENTY_2024!$E:$E,T$5)*38-SUMIFS(BENCHMARK_FENTY_2024!$J:$J,BENCHMARK_FENTY_2024!$E:$E,T$5)*10) -> 227612 | ... X39: =(SUMIFS(BENCHMARK_FENTY_2024!$J:$J,BENCHMARK_FENTY_2024!$E:$E,X$5)*38-SUMIFS(BENCHMARK_FENTY_2024!$J:$J,BENCHMARK_FENTY_2024!$E:$E,X$5)*10) -> 418572 | Z39: =SUM(M39:O39) -> 902524 | AA39: =SUM(P39:R39) -> 855316 | AB39: =SUM(S39:U39) -> 746340 | AC39: =SUM(V39:X39) -> 1136464 | AE39: =SUM(Z39:AA39) -> 1757840 | AF39: =SUM(AB39:AC39) -> 1882804 | AH39: =SUM(AE39:AF39) -> 3640644
H40: vs PY | J40: k | M40: =M38-M39 -> 1804.3 | N40: =N38-N39 -> -150776.8 | O40: =O38-O39 -> -120485.9 | P40: =P38-P39 -> -161997.7 | Q40: =Q38-Q39 -> -122692.5 | R40: =R38-R39 -> -103599.3 | S40: =S38-S39 -> -110640.8 | T40: =T38-T39 -> -127131.5 | ... X40: =X38-X39 -> -224395.8 | Z40: =Z38-Z39 -> -269458.4 | AA40: =AA38-AA39 -> -388289.5 | AB40: =AB38-AB39 -> -386860.8 | AC40: =AC38-AC39 -> -626465.9 | AE40: =AE38-AE39 -> -657747.9 | AF40: =AF38-AF39 -> -1013326.7 | AH40: =AH38-AH39 -> -1671074.6
H41: vs PY | J41: % | M41: =IF(M39=0,0,M40/M39) -> 0.0061570118 | N41: =IF(N39=0,0,N40/N39) -> -0.54244845 | O41: =IF(O39=0,0,O40/O39) -> -0.36343479 | P41: =IF(P39=0,0,P40/P39) -> -0.51386732 | Q41: =IF(Q39=0,0,Q40/Q39) -> -0.37813902 | R41: =IF(R39=0,0,R40/R39) -> -0.48051623 | S41: =IF(S39=0,0,S40/S39) -> -0.49835504 | T41: =IF(T39=0,0,T40/T39) -> -0.5585448 | ... X41: =IF(X39=0,0,X40/X39) -> -0.53609845 | Z41: =Z38/Z39-1 -> -0.29856092 | AA41: =AA38/AA39-1 -> -0.45397198 | AB41: =AB38/AB39-1 -> -0.51834392 | AC41: =AC38/AC39-1 -> -0.55124131 | AE41: =AE38/AE39-1 -> -0.37417962 | AF41: =AF38/AF39-1 -> -0.53820084 | AH41: =AH38/AH39-1 -> -0.45900522
H42: vs Forecast | J42: % | M42: =IF(SUMIFS(FORECAST_2025!$J:$J,FORECAST_2025!$E:$E,M$5)=0,0,(M38-(SUMIFS(FORECAST_2025!$J:$J,FORECAST_2025!$E:$E,M$5)-SUMIFS(FORECAST_2025!$I:$I,FORECAST_2025!$E:$E,M$5)*9))/(SUMIFS(FORECAST_2025!$J:$J,FORECAST_2025!$E:$E,M$5)-SUMIFS(FORECAST_2025!$I:$I,FORECAST_2025!$E:$E,M$5)*9)) -> 1.3134235 | N42: =IF(SUMIFS(FORECAST_2025!$J:$J,FORECAST_2025!$E:$E,N$5)=0,0,(N38-(SUMIFS(FORECAST_2025!$J:$J,FORECAST_2025!$E:$E,N$5)-SUMIFS(FORECAST_2025!$I:$I,FORECAST_2025!$E:$E,N$5)*9))/(SUMIFS(FORECAST_2025!$J:$J,FORECAST_2025!$E:$E,N$5)-SUMIFS(FORECAST_2025!$I:$I,FORECAST_2025!$E:$E,N$5)*9)) -> 0.10929571 | O42: =IF(SUMIFS(FORECAST_2025!$J:$J,FORECAST_2025!$E:$E,O$5)=0,0,(O38-(SUMIFS(FORECAST_2025!$J:$J,FORECAST_2025!$E:$E,O$5)-SUMIFS(FORECAST_2025!$I:$I,FORECAST_2025!$E:$E,O$5)*9))/(SUMIFS(FORECAST_2025!$J:$J,FORECAST_2025!$E:$E,O$5)-SUMIFS(FORECAST_2025!$I:$I,FORECAST_2025!$E:$E,O$5)*9)) -> 0.47933299 | P42: =IF(SUMIFS(FORECAST_2025!$J:$J,FORECAST_2025!$E:$E,P$5)=0,0,(P38-(SUMIFS(FORECAST_2025!$J:$J,FORECAST_2025!$E:$E,P$5)-SUMIFS(FORECAST_2025!$I:$I,FORECAST_2025!$E:$E,P$5)*9))/(SUMIFS(FORECAST_2025!$J:$J,FORECAST_2025!$E:$E,P$5)-SUMIFS(FORECAST_2025!$I:$I,FORECAST_2025!$E:$E,P$5)*9)) -> 0.12776128 | Q42: =IF(SUMIFS(FORECAST_2025!$J:$J,FORECAST_2025!$E:$E,Q$5)=0,0,(Q38-(SUMIFS(FORECAST_2025!$J:$J,FORECAST_2025!$E:$E,Q$5)-SUMIFS(FORECAST_2025!$I:$I,FORECAST_2025!$E:$E,Q$5)*9))/(SUMIFS(FORECAST_2025!$J:$J,FORECAST_2025!$E:$E,Q$5)-SUMIFS(FORECAST_2025!$I:$I,FORECAST_2025!$E:$E,Q$5)*9)) -> 0.43917931 | R42: =IF(SUMIFS(FORECAST_2025!$J:$J,FORECAST_2025!$E:$E,R$5)=0,0,(R38-(SUMIFS(FORECAST_2025!$J:$J,FORECAST_2025!$E:$E,R$5)-SUMIFS(FORECAST_2025!$I:$I,FORECAST_2025!$E:$E,R$5)*9))/(SUMIFS(FORECAST_2025!$J:$J,FORECAST_2025!$E:$E,R$5)-SUMIFS(FORECAST_2025!$I:$I,FORECAST_2025!$E:$E,R$5)*9)) -> 0.16403548 | S42: =IF(SUMIFS(FORECAST_2025!$J:$J,FORECAST_2025!$E:$E,S$5)=0,0,(S38-(SUMIFS(FORECAST_2025!$J:$J,FORECAST_2025!$E:$E,S$5)-SUMIFS(FORECAST_2025!$I:$I,FORECAST_2025!$E:$E,S$5)*9))/(SUMIFS(FORECAST_2025!$J:$J,FORECAST_2025!$E:$E,S$5)-SUMIFS(FORECAST_2025!$I:$I,FORECAST_2025!$E:$E,S$5)*9)) -> 0.09762845 | T42: =IF(SUMIFS(FORECAST_2025!$J:$J,FORECAST_2025!$E:$E,T$5)=0,0,(T38-(SUMIFS(FORECAST_2025!$J:$J,FORECAST_2025!$E:$E,T$5)-SUMIFS(FORECAST_2025!$I:$I,FORECAST_2025!$E:$E,T$5)*9))/(SUMIFS(FORECAST_2025!$J:$J,FORECAST_2025!$E:$E,T$5)-SUMIFS(FORECAST_2025!$I:$I,FORECAST_2025!$E:$E,T$5)*9)) -> -0.0088735363 | ... X42: =IF(SUMIFS(FORECAST_2025!$J:$J,FORECAST_2025!$E:$E,X$5)=0,0,(X38-(SUMIFS(FORECAST_2025!$J:$J,FORECAST_2025!$E:$E,X$5)-SUMIFS(FORECAST_2025!$I:$I,FORECAST_2025!$E:$E,X$5)*9))/(SUMIFS(FORECAST_2025!$J:$J,FORECAST_2025!$E:$E,X$5)-SUMIFS(FORECAST_2025!$I:$I,FORECAST_2025!$E:$E,X$5)*9)) -> 0.15336325 | Z42: =IF(SUMIFS(FORECAST_2025!$J:$J,FORECAST_2025!$C:$C,Z$5)=0,0,(Z38-(SUMIFS(FORECAST_2025!$J:$J,FORECAST_2025!$C:$C,Z$5)-SUMIFS(FORECAST_2025!$I:$I,FORECAST_2025!$C:$C,Z$5)*9))/(SUMIFS(FORECAST_2025!$J:$J,FORECAST_2025!$C:$C,Z$5)-SUMIFS(FORECAST_2025!$I:$I,FORECAST_2025!$C:$C,Z$5)*9)) -> 0.64536773 | AA42: =IF(SUMIFS(FORECAST_2025!$J:$J,FORECAST_2025!$C:$C,AA$5)=0,0,(AA38-(SUMIFS(FORECAST_2025!$J:$J,FORECAST_2025!$C:$C,AA$5)-SUMIFS(FORECAST_2025!$I:$I,FORECAST_2025!$C:$C,AA$5)*9))/(SUMIFS(FORECAST_2025!$J:$J,FORECAST_2025!$C:$C,AA$5)-SUMIFS(FORECAST_2025!$I:$I,FORECAST_2025!$C:$C,AA$5)*9)) -> 0.25440528 | AB42: =IF(SUMIFS(FORECAST_2025!$J:$J,FORECAST_2025!$C:$C,AB$5)=0,0,(AB38-(SUMIFS(FORECAST_2025!$J:$J,FORECAST_2025!$C:$C,AB$5)-SUMIFS(FORECAST_2025!$I:$I,FORECAST_2025!$C:$C,AB$5)*9))/(SUMIFS(FORECAST_2025!$J:$J,FORECAST_2025!$C:$C,AB$5)-SUMIFS(FORECAST_2025!$I:$I,FORECAST_2025!$C:$C,AB$5)*9)) -> 0.088660228 | AC42: =IF(SUMIFS(FORECAST_2025!$J:$J,FORECAST_2025!$C:$C,AC$5)=0,0,(AC38-(SUMIFS(FORECAST_2025!$J:$J,FORECAST_2025!$C:$C,AC$5)-SUMIFS(FORECAST_2025!$I:$I,FORECAST_2025!$C:$C,AC$5)*9))/(SUMIFS(FORECAST_2025!$J:$J,FORECAST_2025!$C:$C,AC$5)-SUMIFS(FORECAST_2025!$I:$I,FORECAST_2025!$C:$C,AC$5)*9)) -> 0.091530526 | AE42: =IF(SUMIFS(FORECAST_2025!$J:$J,FORECAST_2025!$B:$B,AE$5)=0,0,(AE38-(SUMIFS(FORECAST_2025!$J:$J,FORECAST_2025!$B:$B,AE$5)-SUMIFS(FORECAST_2025!$I:$I,FORECAST_2025!$B:$B,AE$5)*9))/(SUMIFS(FORECAST_2025!$J:$J,FORECAST_2025!$B:$B,AE$5)-SUMIFS(FORECAST_2025!$I:$I,FORECAST_2025!$B:$B,AE$5)*9)) -> 0.45310049 | AF42: =IF(SUMIFS(FORECAST_2025!$J:$J,FORECAST_2025!$B:$B,AF$5)=0,0,(AF38-(SUMIFS(FORECAST_2025!$J:$J,FORECAST_2025!$B:$B,AF$5)-SUMIFS(FORECAST_2025!$I:$I,FORECAST_2025!$B:$B,AF$5)*9))/(SUMIFS(FORECAST_2025!$J:$J,FORECAST_2025!$B:$B,AF$5)-SUMIFS(FORECAST_2025!$I:$I,FORECAST_2025!$B:$B,AF$5)*9)) -> 0.090341989 | AH42: =AE42+AF42 -> 0.54344247
H44: Gross Margin | J44: % | M44: =IF(M21=0,0,M38/M21) -> 0.71816176 | N44: =IF(N21=0,0,N38/N21) -> 0.71524049 | O44: =IF(O21=0,0,O38/O21) -> 0.70323814 | P44: =IF(P21=0,0,P38/P21) -> 0.7146845 | Q44: =IF(Q21=0,0,Q38/Q21) -> 0.71325452 | R44: =IF(R21=0,0,R38/R21) -> 0.69407997 | S44: =IF(S21=0,0,S38/S21) -> 0.69749026 | T44: =IF(T21=0,0,T38/T21) -> 0.71268073 | ... X44: =IF(X21=0,0,X38/X21) -> 0.70426112 | Z44: =IF(Z21=0,0,Z38/Z21) -> 0.71253651 | AA44: =IF(AA21=0,0,AA38/AA21) -> 0.70902267 | AB44: =IF(AB21=0,0,AB38/AB21) -> 0.70767773 | AC44: =IF(AC21=0,0,AC38/AC21) -> 0.69153963 | AE44: =IF(AE21=0,0,AE38/AE21) -> 0.71104052 | AF44: =IF(AF21=0,0,AF38/AF21) -> 0.69812172 | AH44: =IF(AH21=0,0,AH38/AH21) -> 0.70527897
H45: GM% PY | J45: % | M45: =IF(M39=0,0,M39/(SUMIFS(BENCHMARK_FENTY_2024!$K:$K,BENCHMARK_FENTY_2024!$E:$E,M$5))) -> 0.73684211 | N45: =IF(N39=0,0,N39/(SUMIFS(BENCHMARK_FENTY_2024!$K:$K,BENCHMARK_FENTY_2024!$E:$E,N$5))) -> 0.73684211 | O45: =IF(O39=0,0,O39/(SUMIFS(BENCHMARK_FENTY_2024!$K:$K,BENCHMARK_FENTY_2024!$E:$E,O$5))) -> 0.73684211 | P45: =IF(P39=0,0,P39/(SUMIFS(BENCHMARK_FENTY_2024!$K:$K,BENCHMARK_FENTY_2024!$E:$E,P$5))) -> 0.73684211 | Q45: =IF(Q39=0,0,Q39/(SUMIFS(BENCHMARK_FENTY_2024!$K:$K,BENCHMARK_FENTY_2024!$E:$E,Q$5))) -> 0.73684211 | R45: =IF(R39=0,0,R39/(SUMIFS(BENCHMARK_FENTY_2024!$K:$K,BENCHMARK_FENTY_2024!$E:$E,R$5))) -> 0.73684211 | S45: =IF(S39=0,0,S39/(SUMIFS(BENCHMARK_FENTY_2024!$K:$K,BENCHMARK_FENTY_2024!$E:$E,S$5))) -> 0.73684211 | T45: =IF(T39=0,0,T39/(SUMIFS(BENCHMARK_FENTY_2024!$K:$K,BENCHMARK_FENTY_2024!$E:$E,T$5))) -> 0.73684211 | ... X45: =IF(X39=0,0,X39/(SUMIFS(BENCHMARK_FENTY_2024!$K:$K,BENCHMARK_FENTY_2024!$E:$E,X$5))) -> 0.73684211 | Z45: =IF(Z39=0,0,Z39/(SUMIFS(BENCHMARK_FENTY_2024!$K:$K,BENCHMARK_FENTY_2024!$C:$C,Z$5))) -> 0.73684211 | AA45: =IF(AA39=0,0,AA39/(SUMIFS(BENCHMARK_FENTY_2024!$K:$K,BENCHMARK_FENTY_2024!$C:$C,AA$5))) -> 0.73684211 | AB45: =IF(AB39=0,0,AB39/(SUMIFS(BENCHMARK_FENTY_2024!$K:$K,BENCHMARK_FENTY_2024!$C:$C,AB$5))) -> 0.73684211 | AC45: =IF(AC39=0,0,AC39/(SUMIFS(BENCHMARK_FENTY_2024!$K:$K,BENCHMARK_FENTY_2024!$C:$C,AC$5))) -> 0.73684211 | AE45: =IF(AE39=0,0,AE39/(SUMIFS(BENCHMARK_FENTY_2024!$K:$K,BENCHMARK_FENTY_2024!$B:$B,AE$5))) -> 0.73684211 | AF45: =IF(AF39=0,0,AF39/(SUMIFS(BENCHMARK_FENTY_2024!$K:$K,BENCHMARK_FENTY_2024!$B:$B,AF$5))) -> 0.73684211 | AH45: =IF(AH39=0,0,AH39/(SUM(BENCHMARK_FENTY_2024!$K:$K))) -> 0.73684211
H46: vs PY | J46: pp | M46: =M44-M45 -> -0.018680341 | N46: =N44-N45 -> -0.021601617 | O46: =O44-O45 -> -0.033603967 | P46: =P44-P45 -> -0.022157605 | Q46: =Q44-Q45 -> -0.02358759 | R46: =R44-R45 -> -0.042762137 | S46: =S44-S45 -> -0.039351841 | T46: =T44-T45 -> -0.024161374 | ... X46: =X44-X45 -> -0.032580985 | Z46: =Z44-Z45 -> -0.024305599 | AA46: =AA44-AA45 -> -0.027819431 | AB46: =AB44-AB45 -> -0.029164371 | AC46: =AC44-AC45 -> -0.045302473 | AE46: =AE44-AE45 -> -0.025801585 | AF46: =AF44-AF45 -> -0.038720387 | AH46: =AH44-AH45 -> -0.03156313
H48: Contribution Margin | J48: € | M48: =SUMIFS(DATA_2025!$V:$V,DATA_2025!$E:$E,M$5) -> 157257.74 | N48: =SUMIFS(DATA_2025!$V:$V,DATA_2025!$E:$E,N$5) -> 100507.16 | O48: =SUMIFS(DATA_2025!$V:$V,DATA_2025!$E:$E,O$5) -> 153342.4 | P48: =SUMIFS(DATA_2025!$V:$V,DATA_2025!$E:$E,P$5) -> 121088.76 | Q48: =SUMIFS(DATA_2025!$V:$V,DATA_2025!$E:$E,Q$5) -> 159338.18 | R48: =SUMIFS(DATA_2025!$V:$V,DATA_2025!$E:$E,R$5) -> 80699.39 | S48: =SUMIFS(DATA_2025!$V:$V,DATA_2025!$E:$E,S$5) -> 81729.83 | T48: =SUMIFS(DATA_2025!$V:$V,DATA_2025!$E:$E,T$5) -> 79332.05 | ... X48: =SUMIFS(DATA_2025!$V:$V,DATA_2025!$E:$E,X$5) -> 150618.05 | Z48: =SUMIFS(DATA_2025!$V:$V,DATA_2025!$C:$C,Z$5) -> 411107.3 | AA48: =SUMIFS(DATA_2025!$V:$V,DATA_2025!$C:$C,AA$5) -> 361126.33 | AB48: =SUMIFS(DATA_2025!$V:$V,DATA_2025!$C:$C,AB$5) -> 277593.36 | AC48: =SUMIFS(DATA_2025!$V:$V,DATA_2025!$C:$C,AC$5) -> 381583.92 | AE48: =SUM(Z48:AA48) -> 772233.63 | AF48: =SUM(AB48:AC48) -> 659177.28 | AH48: =SUM(AE48:AF48) -> 1431410.9
H49: CM PY | J49: € | M49: =M39-M39*0.2 -> 234438.4 | N49: =N39-N39*0.2 -> 222364.8 | O49: =O39-O39*0.2 -> 265216 | P49: =P39-P39*0.2 -> 252201.6 | Q49: =Q39-Q39*0.2 -> 259571.2 | R49: =R39-R39*0.2 -> 172480 | S49: =S39-S39*0.2 -> 177609.6 | T49: =T39-T39*0.2 -> 182089.6 | ... X49: =X39-X39*0.2 -> 334857.6 | Z49: =Z39-Z39*0.2 -> 722019.2 | AA49: =AA39-AA39*0.2 -> 684252.8 | AB49: =AB39-AB39*0.2 -> 597072 | AC49: =AC39-AC39*0.2 -> 909171.2 | AE49: =AE39-AE39*0.2 -> 1406272 | AF49: =AF39-AF39*0.2 -> 1506243.2 | AH49: =AH39-AH39*0.2 -> 2912515.2
H50: vs PY | J50: % | M50: =IF(M49=0,0,(M48-M49)/M49) -> -0.32921509 | N50: =IF(N49=0,0,(N48-N49)/N49) -> -0.54800778 | O50: =IF(O49=0,0,(O48-O49)/O49) -> -0.4218207 | P50: =IF(P49=0,0,(P48-P49)/P49) -> -0.51987315 | Q50: =IF(Q49=0,0,(Q48-Q49)/Q49) -> -0.38614846 | R50: =IF(R49=0,0,(R48-R49)/R49) -> -0.5321232 | S50: =IF(S49=0,0,(S48-S49)/S49) -> -0.53983439 | T50: =IF(T49=0,0,(T48-T49)/T49) -> -0.5643241 | ... X50: =IF(X49=0,0,(X48-X49)/X49) -> -0.55020268 | Z50: =IF(Z49=0,0,(Z48-Z49)/Z49) -> -0.43061445 | AA50: =IF(AA49=0,0,(AA48-AA49)/AA49) -> -0.47223259 | AB50: =IF(AB49=0,0,(AB48-AB49)/AB49) -> -0.53507557 | AC50: =IF(AC49=0,0,(AC48-AC49)/AC49) -> -0.58029476 | AE50: =IF(AE49=0,0,(AE48-AE49)/AE49) -> -0.45086468 | AF50: =IF(AF49=0,0,(AF48-AF49)/AF49) -> -0.56236995 | AH50: =IF(AH49=0,0,(AH48-AH49)/AH49) -> -0.50853101
...

Sheet 2.EXECUTIVE SUMMARY
B2: 2025 Performance Highlights & Strategic Implications
B4: YEAR 1 PERFORMANCE OVERVIEW
B6: Product-Market Fit Validation:
B7: Year 1 exceeded conservative forecast by +31% units and +28% revenue, demonstrating strong market reception and effective go-to-market strategy. The product successfully established its positioning between mass-market and premium competitors.
B8: Loyalty Program Success:
B9: Aura Society membership grew from 45% penetration in January to 65% by December, with the VIP tier (Aura Icon) expanding from 9% to 13% of total sales. This validates the tiered discount strategy and customer retention approach.
B10: Promotional Effectiveness:
B11: Marketing campaigns maintained 4.0+ ROAS during major promotional periods (Black Friday, Single Day, Spring Sale) while preserving healthy margins. Average discount remained controlled at 0-7% baseline, peaking at 18% in November.
B12: Price Positioning:
B13: Launch price of 34€ (vs Fenty 38€, -11%) enabled successful market entry while protecting 71% gross margin and 38% contribution margin throughout the year.
B46: KEY INSIGHTS
B48: • Revenue momentum: Exceeded forecast by average 125% in Q1, stabilizing to +30% by year-end as conservative projections were surpassed
... B52: 2025 FULL YEAR RESULTS
B54: METRIC | C54: RESULT | D54: vs FORECAST | E54: vs BENCHMARK (Fenty)
B55: Total Units | C55: 91.4k | D55: +31% ✅ | E55: -39k (-30%)
B56: Revenue | C56: 2.79M€ | D56: +28% ✅ | E56: -2.15M€ (-43%)
B57: Average Selling Price | C57: 31€ | D57: +3% | E57: -8€ (-21%)
B58: Gross Margin % | C58: 71% | D58: +2pp | E58: +1pp
B59: Contribution Margin % | C59: 51% | D59: +4pp | E59: -2pp
B60: Loyalty Penetration | C60: 65% | D60: - | E60: -
B63: STRATEGIC IMPLICATION FOR YEAR 2
B64: Strong foundation established in Year 1. Focus shifts to closing performance gap with category leader Fenty Beauty (+38k units, +2.15M€ revenue) through strategic pricing optimization while maintaining profitability. Three pricing scenarios modeled to achieve management directive.

Sheet 3.SCENARIOS_PRICING
B2: PRICING SCENARIOS 2026
B3: Data-driven scenarios to close performance gap with category leader
B5: BUSINESS CONTEXT & MANAGEMENT DIRECTIVE
B7: METRIC | C7: 2025 ACTUAL (Aura) | D7: BENCHMARK (Fenty 2024) | E7: GAP TO CLOSE | F7: % INCREASE NEEDED
B8: Total Units Sold | C8: 91.4k | D8: 130.0k | E8: +38.6k | F8: +42%
B9: Revenue | C9: 2.79M€ | D9: 4.94M€ | E9: +2.15M€ | F9: +77%
B10: Average Selling Price | C10: 31€ | D10: 38€ | E10: +8€ | F10: +27%
B12: Management Directive:
B13: Close the performance gap with Fenty Beauty by increasing volume and revenue through strategic pricing levers
B14: Target: Reach 130k units (+38k) and 4.9M€ revenue (+2.1M€) while maintaining profitability
B17: SCENARIO 1: LOYALTY & MIX OPTIMIZATION
B18: Strategic Lever: Accelerate loyalty program adoption - Convert Single customers to tiered members
B20: KPI | C20: 2025 ACTUAL | D20: TARGET | E20: SCENARIO 1 | F20: DELTA vs 2025 | G20: COMMENTS
B21: Total Units (k) | C21: 91.4 | D21: 130.0 | E21: 115.0 | F21: +23.6k (+26%) | G21: Strong loyalty conversion
B22: Revenue (M€) | C22: 2.79 | D22: 4.94 | E22: 3.45 | F22: +0.66M (+24%) | G22: Volume growth compensates ASP
B23: Avg Selling Price (€) | C23: 31 | D23: 38 | E23: 30 | F23: 0€ (stable) | G23: Price unchanged
